Workbook
Name DATA: #REF!

Sheet Module Owners
A1: myHP
A2: Module/Scope | B2: Assign to Component | C2: Owner
A3: Core/Generic for consumer | B3: myHP | C3: Lee, Su-Hau <su-hau.lee1@hp.com>; Huang, Alex <alex.huang@hp.com>
A4: Core/Generic for CMIT | B4: myHP for CMIT | C4: Lee, Su-Hau <su-hau.lee1@hp.com>; Huang, Alex <alex.huang@hp.com>
A5: Consumer Audio Controls | B5: myHP module_Audio Control | C5: Huang, Alex <alex.huang@hp.com>
A6: Consumer myHP Audio Switch | B6: myHP module_Audio Switch | C6: Huang, Alex <alex.huang@hp.com>
A7: Consumer Display Control | B7: myHP module_Display Control | C7: Wang, Vicky (Consumer SWPM) <vicky.wang3@hp.com>
A8: CMIT Programmable Key | B8: myHP module_Programmable Key | C8: Narayanappa, Geetha (CW-Mphasis - SFT) <geetha.narayanappa1@hp.com>; Armstrong, Sridhar (CW) <sridhar.armstrong@hp.com>
A9: SmartCam 1, SmartCam 2 | B9: myHP module_SmartCam | C9: Hsiao, Steven (CW-CW DSAI) <steven.hsiao@hp.com>, Wang, Vicky (Consumer SWPM) <vicky.wang3@hp.com>
A10: SmartCam 3 | B10: myHP module_SmartCam3 | C10: Hsiao, Steven (CW-CW DSAI) <steven.hsiao@hp.com>, Wang, Vicky (Consumer SWPM) <vicky.wang3@hp.com>
A11: CMIT IC1.0 | B11: myHP module_IC1.0 | C11: Armstrong, Sridhar (CW) <sridhar.armstrong@hp.com>
A12: CMIT Smart Experiences | B12: myHP module_Smart Experiences | C12: Guru, Anand <anand.guru@hp.com>
A13: CMIT Audio Controls | B13: myHP module_CMITAudio | C13: Jagdale, Shailesh (CW-Capgemini -WW PM) <shailesh.jagdale@hp.com>
A15: HPX
A16: Module/Scope | B16: Assign to Component | C16: Owner
A17: Core/Generic for consumer | B17: HPX | C17: Lee, Su-Hau <su-hau.lee1@hp.com>; Huang, Alex <alex.huang@hp.com>
A18: Core/Generic for CMIT | B18: HPX for CMIT | C18: Lee, Su-Hau <su-hau.lee1@hp.com>; Huang, Alex <alex.huang@hp.com>
A19: Consumer Audio Controls | B19: HPX_Audio Control | C19: Huang, Alex <alex.huang@hp.com> (NB: Katherine Wei DT: Ken Chiu)
A20: Consumer myHP Audio Switch | B20: HPX_Audio Switch | C20: Huang, Alex <alex.huang@hp.com>
A21: Consumer Display Control | B21: HPX_Display Control | C21: JADHAV, SANJEEV (CW) <sanjeev.jadhav@hp.com> (Wang, Vicky (Consumer SWPM) <vicky.wang3@hp.com>)
A22: CMIT Programmable Key | B22: HPX_Programmable Key | C22: Narayanappa, Geetha (CW-Mphasis - SFT) <geetha.narayanappa1@hp.com>; Armstrong, Sridhar (CW) <sridhar.armstrong@hp.com>
A23: SmartCam 1, SmartCam 2 | B23: HPX_SmartCam 2.0 | C23: Hsiao, Steven (CW-CW DSAI) <steven.hsiao@hp.com> (Wang, Vicky (Consumer SWPM) <vicky.wang3@hp.com>)
A24: SmartCam 3.5 | B24: HPX_SmartCam3.5 | C24: Hsiao, Steven (CW-CW DSAI) <steven.hsiao@hp.com> (Wang, Vicky (Consumer SWPM) <vicky.wang3@hp.com>)
A25: CMIT Smart Experiences | B25: HPX_Smart Experiences | C25: Narayanappa, Geetha (CW-Mphasis - SFT) <geetha.narayanappa1@hp.com>
A26: Pen Control (Consumer) | B26: HPX_Pen Control | C26: Lin, Makayla <makaylal@hp.com> (Patel, Jay (CW) <jay.patel@hp.com>)
A27: 5G | B27: HPX_5G | C27: Huang, Alex <alex.huang@hp.com>
... A37: System Control (Consumer) | B37: HPX_System Control | C37: Tsai, TC CPS SE <tc.tsai@hp.com> (Tsai, Josette <josette.tsai@hp.com>)
A38: System Control (Commercial) | B38: HPX_System Control_CMIT
A39: Battery Manager (Commercial) | B39: HPX_Battery Manager_CMIT
A40: Battery Manager (Consumer) | B40: HPX_Battery Manager | C40: Lin, Edison <edison.lin1@hp.com>
A41: Wi-Fi Sharing (Consumer) | B41: HPX_WiFi Sharing | C41: Tsai, Josette <josette.tsai@hp.com>
A42: Gesture (Consumer) | B42: HPX_Gesture | C42: Tsai, Josette <josette.tsai@hp.com>

Sheet HPX Version
H1: Main Feature | I1: Auto Launch (Except AI platforms) | J1: First Use Flow | K1: Audio Switch (Appears in taskband) | L1: Home Page | M1: Support | N1: Audio Control | Z1: Display Control | AH1: Video Control | BA1: Privacy Alert | BB1: Auto Screen Dimming | BC1: Network Booster | BE1: HP Programmable Key | BG1: System Control | BK1: Settings | BL1: Touchpad | BN1: Screen Time | BP1: Screen Distance | BS1: Pen Control Plus | BW1: WiFi Sharing | BX1: Battery Manager | BY1: Gesture | BZ1: Presence Sensing
H2: Sub-Feature | O2: Audio Levels | P2: Noise Cancellation/ AI Noise Removal | Q2: Equalizer | R2: Speaker Swap | S2: Speaker Configuration (only in Tower PC) | T2: Dynamic Audio | U2: Audio Personalization | V2: AI Spatial Surround | W2: Studio Recording Mode | X2: Audio App Settings | Y2: Restore Default | AA2: Brightness (if Windows Brightness + Windows Use HDR support) | AB2: Contrast | AC2: Mode selections | AD2: LBL Mode | AE2: Mode by application (if Windows Brightness + Windows Use HDR support) | AF2: AIO Modes | AG2: HDR (if Windows Brightness + Windows Use HDR support) | AI2: Auto Frame | AJ2: Low Light | AK2: Backlight | AL2: Background Blur/Image | AM2: Auto and Manual Keystone | AN2: Be-Right-Back | AO2: Video and Image Capture/PDF | AP2: Live Stream | AQ2: Rotate/Zoom/Pan | AR2: Output Resolution | AS2: Skin Color Correction | AT2: Appearance Filter | AU2: Presence Share | AV2: Multicamera (Mixer tab) | AW2: Auto Camera Select | AX2: Gallery Mode | AY2: Anti-Flicker | AZ2: VPU Offloading | BD2: Mode switch (bandwidth prioritization) - non Evo sku only | BF2: App, Website, Folder, File Launch | BH2: Performance Control | BI2: ELP function (OLED Only) | BJ2: Focus mode | BM2: Gestures | BO2: Send a Reminder | BQ2: Alert Options | BR2: Set Preferred Distance | BT2: Battery State | BU2: Upper Barrel Button | BV2: Lower Barrel Botton
A3: Date | B3: Component | C3: Build Type | D3: Version | E3: Part Number(IRS) | F3: Release Notes | G3: Modules Enabled
A4: 44907 | B4: HPX | C4: Dev Build | D4: 25.12249.42.0.A.1 | E4: P0149D-B2G | F4: For PLD on or after 2/24 platforms Changes: First HPX Dev Track build Known issues: 1. HPX doesn't work in offline mode yet 2. HP ID (Sign In) only works in HP network 3. The Welcome page only works in HP network 4. The Support page only works in HP network | G4: 1. Welcome Page 2. Video Control - SmartCam 2 (if the system has SmartCam2 feature byte qj) - SmartCam 3.5.14.0 (if the system has SmartCam3 feature byte qM) 3. Audio Control 4. Display Control 5. Pen Control Plus 6. Support 7. Settings | I4: V | J4: V | K4: V | L4: V | M4: V | N4: V | O4: V | P4: V | Q4: V | R4: V | S4: V | Z4: V | AA4: V | AB4: V | AC4: V | AD4: V | AH4: V | AI4: V | AJ4: V | AK4: V | AL4: V | AM4: V | AN4: V | AO4: V | AP4: V | AQ4: V | AR4: V | AS4: V | AT4: Gallery Mode+AU2+AW2+AW2:AW5 | AU4: V | AV4: V | AW4: V | BK4: V
A5: 44914 | B5: HPX | C5: Dev Build | D5: 25.12251.139.0.A.1 | E5: P0149D-B2J | F5: For PLD on or after 2/24 platforms Main changes: • Update SmartCam to 3.5.20.0 • Redundant control cards will not show • Sound Calibration removed • Performance enhancement • Localization fixes • Fixed HPX shows white screen when launch in offline mode Known issues: 1. HP ID (Sign In) only works in HP network 2. The Support page content only shows in HP network 3. SmartCam2 preview camera is always in "Please wait" state | G5: 1. Welcome Page 2. Video Control - SmartCam 2 (if the system has SmartCam2 feature byte qj) - SmartCam 3.5.20.0 (if the system has SmartCam3 feature byte qM) 3. Audio Control 4. Display Control 5. Pen Control Plus 6. Support 7. Settings | I5: V | J5: V | K5: V | L5: V | M5: V | N5: V | O5: V | P5: V | Q5: V | R5: V | S5: V | Z5: V | AA5: V | AB5: V | AC5: V | AD5: V | AH5: V | AI5: V | AJ5: V | AK5: V | AL5: V | AM5: V | AN5: V | AO5: V | AP5: V | AQ5: V | AR5: V | AS5: V | AT5: V | AU5: V | AV5: V | AW5: V | BK5: V
A6: 44935 | B6: HPX | C6: Integration Build | D6: 25.22302.22.0.A.1 | E6: P0149D-B2L | F6: For PLD on or after 2/24 platforms Main changes: - Update SmartCam to 3.5.30.0 - HPXWC-5009\Flyout menu in Arabic language appears in wrong side (they should appear in right side) - HPXWC-5062\[HPX][L10N] HP registration page not localized with some languages - HPXWC-5027\[SFT_MPH][OTA][VideoControl] Video control module is not visible in HPX V.25.12251.154.0 - Removed Privacy Settings in First Use Flow - Removed Mouse from menu - HPXWC-4921\[AudioSwitch] Click "More audio controls" in Audio Switch will open HPX in home page. - HPXWC-4923\Update translation files to be in line with the latest spec - HPXWC-5143\[AudioControl][L10N] String of "PC audio" have translated incorrect in audio control when change with ES-MX language - HPXWC-5010\SIO2163410 - [SIT][SWT-SW][RPL-H][RPL-U][Win11]: HPX (myhp) Audio Control will force close when expand Output drop down menu then unplug headset. - HPXWC-5046\ SIO2163716 - [SIT][SWT-SW][PHX-H] Equalizer can't be restored defaults click "Restore Defaults" in HPX Audio Control. - HPXWC-4729\ [CGQA] Notification is not visible in ES_MX, DE_DE, FR_FR, PT_BR languages - HPXWC-4959\ [SFT_MPH][Registration][L10N] Registration Page is not localized for Norwegian language - HPXWC-4674\ [SFT_MPH][AudioControl] After clicking on restore defaults button audio presets are disappear. - HPXWC-4525\ [AudioControl] DTS logo also will show up when plugin USB headphone on Tower pc Known issues: 1. Audio Control is not shown on 1st launch of HPX. 2. HP ID (Sign In) only works in HP network 3. The Support page content only shows in HP network 4. SmartCam2 preview camera is always in "Please wait" state 5. Keyboard module is shown | G6: 1. Welcome Page 2. Video Control - SmartCam 2 (if the system has SmartCam2 feature byte qj) - SmartCam 3.5.30.0 (if the system has SmartCam3 feature byte qM) 3. Audio Control 4. Display Control 5. Keyboard 6. Support 7. Settings | I6: V | J6: V | K6: V | L6: V | M6: V | N6: V | O6: V | P6: V | Q6: V | R6: V | S6: V | Z6: V | AA6: V | AB6: V | AC6: V | AD6: V | AH6: V | AI6: V | AJ6: V | AK6: V | AL6: V | AM6: V | AN6: V | AO6: V | AP6: V | AQ6: V | AR6: V | AS6: V | AT6: V | AU6: V | AV6: V | AW6: V | BK6: V
A7: 44942 | B7: HPX | C7: Integration Build | D7: 25.22303.43.0.A.1 | E7: P0149D-B2P | F7: For PLD on or after 2/24 platforms Main changes: Keyboard feature removed Fixed SmartCam2 camera preview always show "Please wait" Sign In/Welcome/Support pages can now work in non-HP network Update Smartcam 3 to 3.5.37.0 • HPXSUP-623\ [Support home page]- The support home page hangs on loading page • HPXSUP-620\ [Offline] - The Device name/SN/PN are missing. • HPXSUP-625\ [Offline] - No translation on offline page • HPXSUP-628\ [Offline] - We still show up Phone card in offline even though the location isn't US/CA • HPXSUP-675\ [Offline] - Support icon and the string are too close together in latest build • HPXSUP-395\ [Offlline -Accessibility] - Serval Failures when run Automated checks • HPXSUP-679\ [Custom protocol &Hotkey] The support page always hangs when enter the myhp://support/device in RUN window • HPXSUP-585\ [Offline]-The contents of the call card and web card on the offline page are not aligned • HPXSUP-586\ [Offline]-When zooming out HPX window, the scroll bar is not as expected on offline page. • HPXSUP-616\ [Offline] - The offline UI is different from Mockup • HPXWC-5401\ Fix local Nuget restore issue for developers machine • HPXWC-5297\ [AudioControl] "Immersive Audio" turns off automatically when re-launch HPX Audio Control with "Immersive Audio" turned on • HPXWC-4638\ [SFT_MPH][AudioControl] Dynamic audio notification does not popup • HPXWC-4953\ SIO2162976 - "Conference" and "Personal" options in HPX Audio Controls/Mic Mode can still be selected when the Jack/USB headset is plugged in. • HPXWC-5319\ [SFT_MPH][AudioControl] Noise reduction toggle button is off by default on first launch. • HPXWC-4952\SIO2162968 - Drag the Equalizer bar to maximum and minimum is not aligned to +6 and -6. • HPXWC-5153\[AudioControl][L10N] String of "stereo" have show incorrect in audio control when change with ES-MX language and select on "quad" or " fiftyOne" • HPXWC-5095\[SFT_MPH][DisplayControl] The time setting is not clear in low blue light scheduler • HPXWC-5121\Integrate Localizations and Replace HPDC.dll file • HPXWC-5161\[SFT_MPH][DisplayControl] LBL scheduler toggle button is not working properly intermittently • HPXWC-4204\[SFT_MPH][Display] LBL Scheduler strings are not fully display when we increase text size to Maximum. • HPXWC-5160\[SFT_MPH][SmartExp][L10N] Extra string for "30 minutes" in Romanian-RO language • HPXWC-5200\[SmartExp]: Loalization support for consent dialog • HPXWC-4982\SIO2162441 - [NB][QTA][SCIT-NPI] Window will auto exit when click "Manage Options" during HPX first use flow • HPXWC-4957\ [SFT_MPH][Registration][L10N] Registration Page is missing in Hebrew Language • HPXWC-5061\[Setup] HPX will crash when first launch with HE-IL language • HPXWC-5183\[Pen] Hover click tooltip not as per figma • HPXWC-5172\[PPR][Audio] Radio button UI is off-center • HPXWC-3465\[AudioControl] All selected\checked buttons seems so strange • HPXWC-4864\[SFT_MPH][Registration] Checkbox UI is not matching with figma design • HPXWC-5195\[SFT_MPH][DisplayControl] Intermittent nothing is happens when we click display control from PC Device o HPXWC-5417\ [EIT] Even after logging out, the screen remains in the logged-in state. • HPXWC-5296\ [Core] "Something went wrong" error message always pop up on some machines • HPXWC-5406\ [PCVideo] Show 'start HP Present Video failed' error when trying to launch Video control. • HPXWC-4946\ SIO2162917 - [Audio] There is no actual function when turning on/off "Immersive Audio" with "Movie" Presets selected • HPXWC-5380\ SIO2165077/SIO2165027 [Quaker][OMENTower][Audio] Shooter/Strategy/RPG preset is not selectable in HPX • HPXWC-5186\ [SFT_MPH][AudioControl] Close button icon displayed in-appropriate. • HPXWC-5231\ [Localization] Chinese dialects appear in the wrong dialect • HPXWC-5075\ SIO2163892 - [Display] Brightness & Contrast display bar is delayed when adjusting it with Mouse/Keyboard • HPXWC-5310\ [AudioControl][L10N] String of "PC audio" have translated incorrect in audio control for CA-ES languages • HPXWC-4931\ State of hamburger menu is not changing in left navigation on hover | G7: 1. Home Page 2. Video Control - SmartCam 2 (if the system has SmartCam2 feature byte qj) - SmartCam 3.5.37.0 (if the system has SmartCam3 feature byte qM) 3. Audio Control 4. Display Control 5. Support 6. Settings 7. Audio Switch | I7: V | J7: V | K7: V | L7: V | M7: V | N7: V | O7: V | P7: V | Q7: V | R7: V | S7: V | T7: V | Z7: V | AA7: V | AB7: V | AC7: V | AD7: V | AH7: V | AI7: V | AJ7: V | AK7: V | AL7: V | AM7: V | AN7: V | AO7: V | AP7: V | AQ7: V | AR7: V | AS7: V | AT7: V | AU7: V | AV7: V | AW7: V | BK7: V
A8: 44954 | B8: HPX | C8: Staging Build | D8: 25.42304.147.0.A.1 | E8: P0149D-B2R | F8: For PLD on or after 2/24 platforms Main changes: Staging Build Update SmartCam to 3.5.39.0 • HPXWC-4499\ Left navigation should be reflected when device name is updated in PCDevicePage • HPXSUP-749\ Update ClientID to HPXWin for warranty API • HPXWC-3820\ [Audio] 13 HPX Integration with Realtek, Sound Research, DTS and Fortemedia DLLs - Security Review • HPXWC-5548\ [Display] Add newer DLL file from portrait service. • HPXWC-4967\ [SFT_MPH][Services]intermittently on clicking on "go to myAccount" in the flyout shows an error • HPXWC-2811\ [CGQA][FirstUse] Font size/color/style are not matching same as design specification for first use flow all screens. • HPXWC-4889\ First use using oversize (and duplicate) PNGs instead of JPG assets for photo images • HPXWC-4523\ [AudioControl] Audio controls card doesn't show up on OMEN • HPXSUP-750\ [Localization]-The support page shows Simplified Chinese on zh-TW machine • HPXWC-4369\ [SFT_MPH][AudioControl] Mic modes are not greyed out when we connect 3.5mm headphone. • HPXWC-5482\ SIO2167043 [Audio] "Noise Removal" will be turned off automatically when re-launch Audio Control with "Noise Removal" turned on • HPXWC-5481\ SIO2167027 [Audio] "Mic Mode" will automatically switch back to "Personal" when re-launch Audio Control with Mic Mode "Conference" selected. • HPXWC-5432\ [SFT_MPH][OTA] PC Device warranty status is mismatch with Support page warranty status • HPXWC-5177\ [UI][Truncation] Truncated text needs an on hover flyout that displays the full string to the user • HPXWC-4249\ [SFT_MPH][Core] Battery life test result exceeding more than 0.01 threshold value for HPX application. • HPXWC-5549\[AudioControl][DynamicAudio] Dynamic Audio notification UI looks wrong when using Chrome • HPXWC-4142\[PPR] HP Registration country dropdown text font should match with country dropdown values font. • HPXWC-5230\[Breadcrumb][AudioSwitch] Deeplinking has an issue with the navigation breadcrumb • HPXWC-4474\[Audio][PPR][Enhancement] "Restore Default Settings" is the correct text using Veneer secondary settings. Currently shows "Restore Defaults" • HPXWC-5185\[SFT_MPH][DisplayControl] Brightness & Contrast background grey line limitation sliders are not able to seen. • HPXWC-5591\SIO2167802 - [SIT][FIT-FUN[CarmenK][HPX0.5_OTA] "Brightness & Contrast" can't recover default in Display Control on clicking "Restore defaults" • HPXWC-5075\ SIO2163892 - [Display] Brightness & Contrast display bar is delayed when adjusting it with Mouse/Keyboard • HPXWC-5413\[HomePg] Application crashes from Interstitial pages • HPXWC-5567\[SFT_MPH][Core] PC Device UI shows mostly empty on changing back the High contrast to None. • HPXWC-5544\[AudioControl] Health sliders under I/O master volumes are lagging • HPXWC-5501\ [AudioControl] All buttons and sliders should be disable when the platform has no input and output deivces • HPXWC-5703\ [Core][Performance] Memory leak observed upon clicking on different module from left navigation panel • HPXWC-5704\ [Core] Webview instances are never destroyed, eventually leading to memory full/crash • HPXWC-5550\ SIO2167393 - [SIT][SWT-SW][CZN-H][HPX0.5_OTA]"Connect" button show cut off when offline in myHP\home page on AB2 image. • HPXWC-5750\ [Settings] Change Copyright to 2023 | G8: 1. Home Page 2. Video Control - SmartCam 2 (if the system has SmartCam2 feature byte qj) - SmartCam 3.5.39.0 (if the system has SmartCam3 feature byte qM) 3. Audio Control 4. Display Control 5. Support 6. Settings 7. Audio Switch | I8: V | J8: V | K8: V | L8: V | M8: V | N8: V | O8: V | P8: V | Q8: V | R8: V | S8: V | T8: V | Z8: V | AA8: V | AB8: V | AC8: V | AD8: V | AH8: V | AI8: V | AJ8: V | AK8: V | AL8: V | AM8: V | AN8: V | AO8: V | AP8: V | AQ8: V | AR8: V | AS8: V | AT8: V | AU8: V | AV8: V | AW8: V | BK8: V
A9: 44957 | B9: HPX | C9: Staging Build | D9: 25.42305.150.0.A.1 | E9: P0149D-B2T | F9: For PLD on or after 2/24 platforms Main changes: Staging Build Update SmartCam to 3.5.39.0 HPXWC-5815\[myAccount] HPX closed when we click 'go to my account' in ITG build. HPXWC-5184\[SFT_MPH][OTA][Settings] Intermittently HPX version is displaying as NULL HPXWC-5772\[UI] Icons are not properly visible in some resolutions. HPXWC-5752\[PPR] Square corner with different color near rounded corner HPXWC-4978\[SFT_MPH][OTA] Text cut-off is seen when we minimize the Privacy Settings page. HPXWC-5749\[PCDevice] Warranty status icon for "Unknown" mismatch with figma on ultron laptop HPXWC-5162\[SFT_MPH][DisplayControl] Text box cutoff seen when we navigate using tab button HPXWC-5799\[DevOps] 0 version bulk script needs to be skipped when there is not file under ./change folder HPXWC-5677\[CGQA] myHP icon is missing in internet connection screen title-bar. HPXWC-5470\[Core] LocalizationJplugin is not providing 5 character locale HPXWC-5816\[Support][Deeplink] Support card on PC Device page takes you to top level Support module HPXWC-5797\[Pen] Feature-specific (Pen? Wacom.ISD.SettingsClient.dll) binary embedded in the Shell (UWP or DesktopExtension) HPXWC-5552\[PCVideo] HPPV screen can not open again when restart PC then launch HPPV screen again HPXWC-5735\[Analytics] PC Mouse generating unnecessary events on hover HPXWC-5355\[AudioControl] Sound does not change when increase or decrease the ft and db value when click play test button HPXWC-5474\[HPPK][PPR] Modal window: Application, header typography is incorrect | G9: 1. Home Page 2. Video Control - SmartCam 2 (if the system has SmartCam2 feature byte qj) - SmartCam 3.5.39.0 (if the system has SmartCam3 feature byte qM) 3. Audio Control 4. Display Control 5. Support 6. Settings 7. Audio Switch | I9: V | J9: V | K9: V | L9: V | M9: V | N9: V | O9: V | P9: V | Q9: V | R9: V | S9: V | T9: V | Z9: V | AA9: V | AB9: V | AC9: V | AD9: V | AH9: V | AI9: V | AJ9: V | AK9: V | AL9: V | AM9: V | AN9: V | AO9: V | AP9: V | AQ9: V | AR9: V | AS9: V | AT9: V | AU9: V | AV9: V | AW9: V | BK9: V
A10: 44963 | B10: HPX | C10: Staging Build | D10: 25.42305.5.0.A.1 | E10: P0149D-B2X | F10: For PLD on or after 2/24 platforms Main changes: Knwon issue: Display Control UI is incorrect Fixed issues: SIO2167051 - [SIT][FIT-MM][Zonin][RPL-S]The actual function is still working after the "Noise Removal" is turned off in HPX Audio Control. SIO2168795 - [SIT][SWT-SW][23C1][Arctic_U][RPL]Noise Reduction can not be switch to off when plugin device SIO2167712 - [SIT][FIT-MM][Zonin][ADL-S][HPX0.5_OTA] There is no "Audio control" item and "Video control" item in Device/PC device page after launch the HPX.(AB2&ABJ) SIO2169145 - [SIT][SWT-SW][Montes-ADL][HPX0.5_OTA] There is no smartcam in HPX after OTA upgrade from MS store. (HPX v25.42305.150.0) SIO2169133 - [SIT][SWT-SW][Contino][Barcelo][HPX0.5_OTA]There is no smartcam in HPX after OTA upgrade from MS store. (HPX v25.42305.150.0) SIO2169215 - [SIT][SWT-SW][ADL][HPX0.5_OTA]There is no Video Control in myHP(HPX). SIO2169540 - [SIT][FIT-MM][Zonin][ADL-S][HPX0.5_OTA] The button of "Conference" or "Personal" with "Mic mode" is not grayed out when turn off "Noise Reduction" opption after launch HPX app. SIO2169158 - [SIT][SWT-SW][BCL-R][Win11][PV1][HPX0.5_OTA] HPX(myHP) Version show 25.22304.113.0 in About page but should be 25.42305.150.0 (F/R:1/2 units) HPXWC-5945\[AudioControl] Mic Mode will not grey out when turn off Noise Reduction HPXSUP-767\[OCChat] Chat Page will be loading sometimes when change country frequently. HPXWC-5926\[Home] Welcome Banner should not have comma when User is signed in to the account HPXWC-5501\[AudioControl] All buttons and sliders should be disable when the platform has no input and output deivces HPXWC-4305\[SFT_MPH][CoreNav][Accessibility] Narrator fails to read expected action when hamburger menu is opened/closed. myHP icon read as custom HPXWC-6015\[Home Page] Set new static height for Recommended for you section of Home page HPXWC-5880\[Audio] SIO2168816 - "Noise Reduction" can not be turned off in HPX HPXWC-5598\SIO2167712/SIO2169145/SIO2169133/SIO2169215 - [Zonin/Montes/Contino/Weller][HPX0.5_OTA] No "Audio control" item and "Video control" item in Device/PC device page after launch (IsVisible) HPXWC-5724\[SFT_MPH][AudioControl] Noise Removal is not working (IsVisible) HPXWC-5563\[Accessibility] There is no response when using Enter key to open notification and profile icons. HPXWC-5764\[Communications]In Spanish-Spain Language, Mismatch in toggle alignment in Settings-Notifications page HPXWC-5763\[Communications]In Catalan - Ca Language, Mismatch in toggle alignment in Settings-Notifications page HPXWC-4829\[HPX 0.5] Icon: PC Unselected Device icon is incorrect HPXWC-4828\[HPX 0.5] Icon: Devices icon and color is incorrect | G10: 1. Home Page 2. Video Control - SmartCam 2 (if the system has SmartCam2 feature byte qj) - SmartCam 3.5.39.0 (if the system has SmartCam3 feature byte qM) 3. Audio Control 4. Display Control 5. Support 6. Settings 7. Audio Switch | I10: V | J10: V | K10: V | L10: V | M10: V | N10: V | O10: V | P10: V | Q10: V | R10: V | S10: V | T10: V | Z10: V | AA10: V | AB10: V | AC10: V | AD10: V | AH10: V | AI10: V | AJ10: V | AK10: V | AL10: V | AM10: V | AN10: V | AO10: V | AP10: V | AQ10: V | AR10: V | AS10: V | AT10: V | AU10: V | AV10: V | AW10: V | BK10: V
A11: 44970 | B11: HPX | C11: Staging Build | D11: 25.42306.27.0.A.1 | E11: P014J4-B2B | F11: For PLD on or after 2/24 platforms Main changes: • HPXWC-6190\[Audio] Enhancement - Turn OFF "Restore Defaults" button within audio control on HPX 0.5 to support 09Feb23 release • HPXWC-5960\[Communications] Investigate to fix toggle button alignment issue • HPXWC-5396\[Home] Missing PC connect(5G) from home page • HPXWC-5865\[SFT_MPH][Homepage] Narrator is not able to read the selected text (control your pc header). • HPXWC-4401\[HighContrast] Turn on High Contrast theme, open one page, cannot see the Icon in the left menu • HPXWC-5778\[SFT_MPH][FirstUse][Privacy] About Your Privacy Page has not shown when all the consent value are set to unknown. • HPXWC-6149\[Offline] Error shows when disconnect the network. HPX does not work offline. • HPXWC-6239\[5G] HPX crashed when use cellular data connection • HPXWC-6142\[AudioControl] Dynamic Audio content is not classified correctly • HPXWC-6063\[AudioControl] Audio presets default option is "Voice" instead of "Music" in Arti-A machine • HPXWC-4399\[PCConnect] Cannot navigate to the PCConnect module through the link of PC device module • JWEB-5894\[Analytics] [Instrumentation] Privacy Setting Analytics Data • HPXWC-6120\[FirstUse][HPID] HP registration and HP privacy missing when launch HPX at the first time • HPXWC-5165\[SFT_MPH][SmartExp][L10N] UI is not localized for Smart Experiences cards in Bahasa Indonesian (ID) language • HPXWC-6202\[Core] Support is missing on Home page | G11: 1. Home Page 2. Video Control - SmartCam 2 (if the system has SmartCam2 feature byte qj) - SmartCam 3.5.39.0 (if the system has SmartCam3 feature byte qM) 3. Audio Control 4. Display Control 5. Support 6. Settings 7. Audio Switch | I11: V | J11: V | K11: V | L11: V | M11: V | N11: V | O11: V | P11: V | Q11: V | R11: V | S11: V | T11: V | Z11: V | AA11: V | AB11: V | AC11: V | AD11: V | AH11: V | AI11: V | AJ11: V | AK11: V | AL11: V | AM11: V | AN11: V | AO11: V | AP11: V | AQ11: V | AR11: V | AS11: V | AT11: V | AU11: V | AV11: V | AW11: V | BK11: V
A12: 44977 | B12: HPX | C12: Production Build | D12: 25.52307.30.0.A.1 | E12: P014J4-B2C | F12: For PLD on or after 2/24 platforms Main changes: • HPXWC-6368\[SFT_MPH][Registration] Stuck on loading screen after registering for HP Registration. • HPXWC-5962\ SIO2169236 The "Mic mode" was not switched in Audio on clicking "Conference" or "Personal" in notification to choose "Mic mode" during zoom video call • HPXWC-5006\SIO2163295/SIO2162832/SIO2162826 - [Sparty][Zonin] "Conference" and "Personal" function is not different under Input > Noise Reduction > MIC mode • HPXWC-5695\ SIO2168322 - [SIT][FIT-FUN[CarmenK][GML-R][HPX0.5_OTA] Sound is noise during Microsoft teams meeting and turn on "Noise Removal" button in Audio control. • HPXWC-6332\ SIO2171432 - [SIT][Frostbreath][Raphael][HPX0.5_OTA] Speaker Configuration dB setting can't keep after reopen myHP. • HPXWC-2865\[Audio][AUID] Missing AUIDs in Speaker Configuration • HPXWC-6258\[Device] Direction of Arrow in Back button isn't aligned with right to left system (Saudi Arabia and Hebrew Languages) • HPXWC-6402\[Display Control] Display Control is not localized in nl-NL(Dutch) Language • HPXWC-6303\SIO2171361 - [SIT][SWT-SW][22C2][Arctic][RPL]HPX0.5_OTA]Click Get Details not Loc to CH in AB2 Region • HPXWC-5998\[AudioControl] Noise Removal will be turned on after clicking Restore Default button • HPXWC-5878\[Video] Add launch button and icon to secondary page for Smartcam 3+ systems | G12: 1. Home Page 2. Video Control - SmartCam 2 (if the system has SmartCam2 feature byte qj) - SmartCam 3.5.39.0 (if the system has SmartCam3 feature byte qM) 3. Audio Control 4. Display Control 5. Support 6. Settings 7. Audio Switch | I12: V | J12: V | K12: V | L12: V | M12: V | N12: V | O12: V | Q12: V | R12: V | S12: V | Z12: V | AA12: V | AB12: V | AC12: V | AD12: V | AH12: V | AI12: V | AJ12: V | AK12: V | AL12: V | AM12: V | AN12: V | AO12: V | AP12: V | AQ12: V | AR12: V | AS12: V | AT12: V | AU12: V | AV12: V | AW12: V | BK12: V
A13: 44981 | B13: HPX | C13: Production Build | D13: 25.52308.38.0.A.1 | E13: P014J4-B2D | F13: For PLD on or after 2/24 platforms Main changes: P1: 1. HPXWC-6776\ [Video] Integrate Smartcam into HPX v3.5.46 2. HPXWC-6249\[Core][HomePg] Launch time to full home page is ~22 seconds 3. HPXWC-6685\[AudioControl] Speaker Configuration and Sound Calibration show on unsupported machine 4. HPXWC-6515\[PCDevice] Delay in loading PC device page 5. HPXWC-6593\[PCVideo] No response when close HPPV then click "video control" button on HPX on SC3 6. HPXWC-6514\[AudioControl] Audio controls page load time need about 5 seconds or longer sometimes 7. HPXWC-6368\[SFT_MPH][Registration] Stuck on loading screen after registering for HP Registration. 8. HPXWC-6401\[London] Hotkey response is ~20 seconds 9. HPXWC-5006\SIO2163295/SIO2162832/SIO2162826 - [Sparty][Zonin] "Conference" and "Personal" function is not different under Input > Noise Reduction > MIC mode 10. HPXWC-5695\ SIO2168322 - [SIT][FIT-FUN[CarmenK][GML-R][HPX0.5_OTA] Sound is noise during Microsoft teams meeting and turn on "Noise Removal" button in Audio control. 11. HPXWC-5998\[AudioControl] Noise Removal will be turned on after clicking Restore Default button 12. HPXWC-5878\[Video] Add launch button and icon to secondary page for Smartcam 3+ systems P2: 1. HPXWC-6367\ [SFT_MPH][SettingsPage] Not able to scroll in privacy tab to view "To review your privacy setting, click here" on text size at maximum 2. HPXWC-6734\SIO2173473 [Localization] The default text of the options in Microphone Mode will be cut off when launch HPX. 3. HPXWC-6240\SIO2170872 - [NB][Varcolac][PV][IEC] Offline messages not seen easily when open HPX without network on OLED panel SKUs. 4. HPXWC-6692\[SFT_MPH][AudioControl] Output and input dropdown alignment is not proper. 5. HPXWC-6420\[SFT_MPH][Registration] HP registration missing when launch HPX at the first time. 6. HPXWC-6260\SIO2169521 Missing "Use the HP Virtual Assistant" and "Run hardware diagnostics" under HPX/Support/Device support/Guided troubleshooting with build 7. HPXWC-6304\[SFT_MPH][SupportPage] Support page icon in the left navigation menu mismatches when navigated other than the left navigation menu 8. HPXWC-6264\[AudioControl] HP Dynamic audio notification popped up on unsupported machine 9. HPXWC-6595\[PCVideo] Video Controls button on blank Video Controls page minimizes SmartCam 3 instead of bringing to foreground 10. HPXWC-6406\[PCVideo] New HPPV screen pops up again and always show initialization screen when keep HPPV foreground and quickly click "video controls" button twice 11. HPXWC-6408\SIO2171255 - [Hokie] "Go to my account" launches in web browser. 12. HPXWC-6618\Update HPDC.dll Ver. 5.1.0.058 with HP Display Control NuGet package and include it in HPX 13. HPXWC-6258\[Device] Direction of Arrow in Back button isn't aligned with right to left system (Saudi Arabia and Hebrew Languages) 14. HPXWC-6365\[SFT_MPH][SmartExp][L10N] Contents present in the alert notification are not localized for ID language 15. HPXWC-6402\[Display Control] Display Control is not localized in nl-NL(Dutch) Language 16. HPXWC-6303\SIO2171361 - [SIT][SWT-SW][22C2][Arctic][RPL]HPX0.5_OTA]Click Get Details not Loc to CH in AB2 Region | G13: 1. Home Page 2. Video Control - SmartCam 2 (if the system has SmartCam2 feature byte qj) - SmartCam 3.5.46.0 (if the system has SmartCam3 feature byte qM) 3. Audio Control 4. Display Control - display control driver: 5.1.0.058 5. Support 6. Settings 7. Audio Switch | I13: V | J13: V | K13: V | L13: V | M13: V | N13: V | O13: V | P13: V | Q13: V | R13: V | S13: V | Z13: V | AA13: V | AB13: V | AC13: V | AD13: V | AH13: V | AI13: V | AJ13: V | AK13: V | AL13: V | AM13: V | AN13: V | AO13: V | AP13: V | AQ13: V | AR13: V | AS13: V | AT13: V | AU13: V | AV13: V | AW13: V | BK13: V
A14: 44991 | B14: HPX | C14: Production Build | D14: 25.52309.52.0.A.1 | E14: P014J4-B2E | F14: For PLD on or after 2/24 platforms Main changes: • HPXWC-7000\ [FirstLaunch] Registration and Privacy shows after myhp to HPX update • HPXWC-6564\ HPX not usable after deep linking, when user is on any "Recommended for you" page • HPXWC-6740\We do not get distinguishing EntryPoint for autolunch • HPXWC-3877\[PCConnect] Usage data not display under 5G Connectivity. • HPXWC-5851\ [Settings] When we minimize the Settings Notification page, text is cut off and not able to scroll down the screen • HPXWC-6021\ [LeftNav] Left side bar elements not having AUID • HPXWC-6796\ PCDevice depends on Fusion for registry reads (but claims it doesn't) • HPXWC-6332\ SIO2171432 - [SIT][Frostbreath][Raphael][HPX0.5_OTA] Speaker Configuration dB setting can't keep after reopen myHP. • HPXWC-6729\ [CGQA][L10N] "Connect internet" screen is not localized as expected for RTL languages. • HPXWC-6704\ [SFT_MPH][PCDevice] Change system's name, observe previous system's name for a second, then new name shown • HPXWC-6542\ [AudioControls] Seeing cut off on audio screen on making text bigger. • HPXWC-6348\ [SFT_MPH][DisplayControl] Clicking Modes, Restore Default button continuously 15-to-20-time, Contrast slider flickers to 0 value and come back to previous selected value • HPXWC-6884\ [SFT_MPH][DisplayControl] We can save the Timer without selecting either turn-on and turn-off Timer from LBL scheduler • HPXWC-6816\ [SFT_MPH][DisplayControl] Cut off is seen when we navigate to any modes using tab button • HPXWC-6760\[HPX] Build version is not synchronized in top bar & about/settings on non-production build. • HPXWC-6387\SIO2167713 - [Bucky] Speaker 3 ban changed to match headset value, even preset of headset is disabled. • HPXWC-6746\BackgroundTask error handling clean up - hp-af/app-lifecycle • HPXWC-5000\[SFT_MPH][OTA][Settings] We seen some delay in Setting page to load in HPX Module • HPXWC-6323\[SFT_MPH][DisplayControl] Brightness slider flickering is seen when we drag slider randomly in between left to right • HPXWC-5424\[SFT_MPH][DisplayControl] Brightness & Contrast Analytics data ID's not generated • HPXSUP-1033\[Support page] The offline page flashed When clicking 'Support' on the left navigation bar • HPXSUP-762\[HPOne & Support hotkey] - Press hotkey to open HPX, sign in profile and then press Hotkey, it doesn't work • HPXWC-6796\PCDevice depends on Fusion for registry reads (but claims it doesn't) • HPXWC-6140\SIO2170101 - [SIT][FIT-MM][Zonin] "Noise Reduction" in Audio Control cannot be turned on when clicking the "Restore Defaults" button with "Noise Reduction" turned off. • HPXWC-6329\As a user, I don't want to send serial number without my consent during login • HPXWC-5361\ [SFT_MPH][CoreNav][Accessibility] Narrator fails to read some strings on Top App bar • HPXWC-6367\[SFT_MPH][SettingsPage] Not able to scroll in privacy tab to view "To review your privacy setting, click here" on text size at maximum | G14: 1. Home Page 2. Video Control - SmartCam 2 (if the system has SmartCam2 feature byte qj) - SmartCam 3.5.46.0 (if the system has SmartCam3 feature byte qM) 3. Audio Control 4. Display Control - display control driver: 5.1.0.058 5. Support 6. Settings 7. Audio Switch | I14: V | J14: V | K14: V | L14: V | M14: V | N14: V | O14: V | P14: V | Q14: V | R14: V | S14: V | Z14: V | AA14: V | AB14: V | AC14: V | AD14: V | AH14: V | AI14: V | AJ14: V | AK14: V | AL14: V | AM14: V | AN14: V | AO14: V | AP14: V | AQ14: V | AR14: V | AS14: V | AT14: V | AU14: V | AV14: V | AW14: V | BK14: V
A15: 44998 | B15: HPX | C15: Production Build | D15: 25.52310.68.0.A.1 | E15: P014J4-B2G | F15: Main changes: • Updated SmartCam to v3.5.50 • HPXWC-7098\[SFT_MPH][OTA][SmartCamv2] Smartcam V2 Functionality's are not working. • HPXWC-7108\[Settings] App crashes when double click 'click here' on settings page. • HPXWC-7132\[AudioControl] No Audio under PCDevice and on home page. • HPXWC-7030\[AudioControl] The toggle default status is Off for Noise reduction • HPXWC-7025\[SFT_MPH][OTA][AudioControl] Equalizer band cut off is seen in 32 slider • HPXWC-6710\[AudioControl] Immersive audio doesn't work on first time • HPXWC-7027\[AudioControl] General Features is shown and expandable in the side panel when there are no options • HPXWC-7175\[DisplayControl][HighContrast]Brightness & Contrast icons are missing when we select Aquatic, Dusk, Night sky themes. • HPXWC-6935\[SFT_MPH][Core] Text Cut-Off seen using tab button when we make text size is bigger to 225%. • HPXSUP-1119\[Support Home Page][Skeleton] - The support home page and RN's skeleton native page are appears at the same time on 4K display machine. • HPXWC-6895\[Core][LeftNav] Background color is not correct with High contrast black theme • HPXWC-5187\[AudioSwitch][L10N] MyHP Audio Switch UI does not display as RTL with HE-IL language. • HPXWC-7207\[Accessibility] myHP icon should not be navigable. • HPXWC-5990\SIO2169341 - [SIT][SWT-SW][HPX0.5_OTA] The Manage notifications/Desktop... items still show enable state and can click toggle when clicked Home item and the re-clicked Settings/Notification with offline mode. • HPXWC-6922\[SFT_MPH][AudioControl] Noise reduction and mic mode getting flickered when we select headset from input dropdown bar. • HPXSUP-585\[Offline]-The contents of the call card and web card on the offline page are not aligned • HPXWC-5235\SIO2164872 - [SIT][SWT-SW][22H2-SFR][Blizzard_L] Click HPX audio Multi-Streaming icon "i" not show information • HPXWC-6735\[AudioControl] MIC Mode default setting is Personal in HPX. • HPXWC-6767\[AudioControl] Mic Mode still shows up when turn off Noise Reduction and then switch back to Internal mic • HPXWC-6141\SIO2170133 - [SIT][Zonin][HPX0.5_OTA] "Noise Removal" function is turned on by default after 1st launch of HPX Audio Control • HPXWC-6884\[SFT_MPH][DisplayControl] We can save the Timer without selecting either turn-on and turn-off Timer from LBL scheduler • HPXWC-6820\[SFT_MPH][DisplayControl][HighContrast] Brightness & Contrast slider is missing when we select Aquatic, Desert, Dusk, Night sky themes. • HPXWC-4204\[SFT_MPH][Display] LBL Scheduler strings are not fully display when we increase text size to Maximum. | G15: 1. Home Page 2. Video Control - SmartCam 2 (if the system has SmartCam2 feature byte qj) - SmartCam 3.5.50.0 (if the system has SmartCam3 feature byte qM) 3. Audio Control 4. Display Control - display control driver: 5.1.0.058 5. Support 6. Settings 7. Audio Switch | I15: V | J15: V | K15: V | L15: V | M15: V | N15: V | O15: V | P15: V | Q15: V | R15: V | S15: V | Z15: V | AA15: V | AB15: V | AC15: V | AD15: V | AH15: V | AI15: V | AJ15: V | AK15: V | AL15: V | AM15: V | AN15: V | AO15: V | AP15: V | AQ15: V | AR15: V | AS15: V | AT15: V | AU15: V | AV15: V | AW15: V | BK15: V
A16: 44999 | B16: HPX | C16: Integration Build | D16: 25.22310.141.0.A.1 | E16: P014J4-B2H | F16: Main changes: Network Booster and System Control enabled for testing on 23C2 Bopeep,Willie, Herbie, Oski, Tuffy, Sammy. Please only focus on testing the Network Booster and System Control and ignore other features. | G16: 1. Home Page 2. Video Control - SmartCam 2 (if the system has SmartCam2 feature byte qj) - SmartCam 3.5.50.0 (if the system has SmartCam3 feature byte qM) 3. Audio Control 4. Display Control - display control driver: 5.1.0.058 5. Network Booster 6. System Control 7. Support 8. Settings 9. Audio Switch | I16: V | J16: V | K16: V | L16: V | M16: V | N16: V | O16: V | P16: V | Q16: V | R16: V | S16: V | Z16: V | AA16: V | AB16: V | AC16: V | AD16: V | AH16: V | AI16: V | AJ16: V | AK16: V | AL16: V | AM16: V | AN16: V | AO16: V | AP16: V | AQ16: V | AR16: V | AS16: V | AT16: V | AU16: V | AV16: V | AW16: V | BC16: V | BD16: V | BG16: V | BH16: V | BK16: V
A17: 45005 | B17: HPX | C17: Production Build | D17: 25.52311.74.0.A.1 | E17: P014J4-B2K | F17: Main changes: • HPXWC-7233\[AudioControl] Audio control still shows up when standalone app exist • HPXWC-7473\[Video] Integrate smartcam 3.5.54 into HPX • HPXWC-7334\Add HP.PrivacyConsentUI nuget 2.1.30 and Fusion Analytics 2.1.23 to HPX to support Narrator fixes | G17: 1. Home Page 2. Video Control - SmartCam 2 (if the system has SmartCam2 feature byte qj) - SmartCam 3.5.54.0 (if the system has SmartCam3 feature byte qM) 3. Audio Control 4. Display Control - display control driver: 5.1.0.058 5. Support 6. Settings 7. Audio Switch | I17: V | J17: V | K17: V | L17: V | M17: V | N17: V | O17: V | P17: V | Q17: V | R17: V | S17: V | Z17: V | AA17: V | AB17: V | AC17: V | AD17: V | AH17: V | AI17: V | AJ17: V | AK17: V | AL17: V | AM17: V | AN17: V | AO17: V | AP17: V | AQ17: V | AR17: V | AS17: V | AT17: V | AU17: V | AV17: V | AW17: V | BK17: V
A18: 45006 | B18: HPX | C18: Production Build | D18: 25.52311.89.0.A.1 | E18: P014J4-B2L | F18: Main changes: • HPXWC-7499\ [AudioControl] EQ vertical axis UI isn't consistent with its design • HPXWC-7443\ [SFT_MPH][Registration][Accessibility] Automated checks test is failing for Country Dropdown in Registration Page. • HPXWC-7474\ [HomePage][AUID] Some text elements AUID missing on home page • HPXWC-7184\ [PCDevice][HighContrast] Windows 11 & 10 issues on High Contrast theme • HPXWC-7374\ SIO2176217 - [SIT][SWT-SW][RPL][Win11] The warranty of HPX and HPSA's are shown differently. • HPXWC-7523\ [RGBKB] Narrator should not read Slider icon as "SVG image - image" • HPXWC-7243\ auto launch events not being captured correctly • HPXSUP-1102\[VA] - 5G card can't be displayed on 5G PC. • HPXWC-7228\[SFT_MPH][DisplayControl] In LBL Scheduler page UI string is not matching with figma and LBL Scheduler page cross icon is over-lapping with application existing cross icons. • HPXWC-5361\[SFT_MPH][CoreNav][Accessibility] Narrator fails to read some strings on Top App bar • HPXWC-7207\[Accessibility] myHP icon should not be navigable. • HPXWC-7158\[SFT_MPH][Services][HighContrast] No change of states for the avatar • HPXWC-7358\[CGQA][NPS] Notification is not visible without app launch, after app upgrade myHP to HPX | G18: 1. Home Page 2. Video Control - SmartCam 2 (if the system has SmartCam2 feature byte qj) - SmartCam 3.5.54.0 (if the system has SmartCam3 feature byte qM) 3. Audio Control 4. Display Control - display control driver: 5.1.0.058 5. Support 6. Settings 7. Audio Switch | I18: V | J18: V | K18: V | L18: V | M18: V | N18: V | O18: V | P18: V | Q18: V | R18: V | S18: V | Z18: V | AA18: V | AB18: V | AC18: V | AD18: V | AH18: V | AI18: V | AJ18: V | AK18: V | AL18: V | AM18: V | AN18: V | AO18: V | AP18: V | AQ18: V | AR18: V | AS18: V | AT18: V | AU18: V | AV18: V | AW18: V | BK18: V
A19: 45012 | B19: HPX | C19: Production Build | D19: 25.52312.97.0.A.1 | E19: P014J4-B2N | F19: Main changes: RC build for 2023.03.B • HPXWC-7667\[DisplayControl] Integrate HPDC dll Ver. 5.1.60.0 with HP.Display Control • HPXWC-7566\ [CGQA] "Share your feedback" toggle status does not remain same after relaunch app • HPXWC-7660\ [High contrast] Hp logo in first launch privacy and registration page not visible when mode is changed to highcontrast black theme • HPXWC-6848\ [SFT_MPH][AudioControl] No presets are selected when we unplugged the 3.5m headset on OMEN platforms • HPXSUP-585\ [Offline]-The contents of the call card and web card on the offline page are not aligned • HPXWC-7245\ SIO2176025/SIO2176243 [SIT][OTA] Platform info shows NA in myHP/Devices/PC Device • HPXWC-6386\ [AudioControl] Remove 3 Band EQ from the UI for most consumer platforms • HPXWC-7437\ Do not show Privacy settings Tab for Corp images In case HP Privacy setting app does not exists • HPXWC-7554\ NPS Toast Notification Crash • HPXWC-7624\SIO2177410/SIO2177457- [HarryPotter][AutoLaunch] HPX won't be launched automatically after reboot system. • HPXWC-7549\[SFT_MPH][DisplayControl][Accessibility] In Display P3 (Photo and Video) mode slightly cut-off is seen for (d) word when we navigate using tab button • HPXWC-7612\[AudioControl] It doesn't navigate to Audio Controls page after clicking "More Audio Controls" link in Audio Switch • HPXSUP-1125\[SFT_MPH][SupportPage][HighContrast] While Offline the background color is not applied properly • HPXWC-7481\[Audio Control][AUID] Some text elements AUID missing on Audio Control module • HPXWC-7491\[PC Device][AUID] Some text elements AUID missing in PC Device module • HPXWC-7530\[SFT_MPH][OTA][AudioControl][HighContrast] When we apply High contrast themes, We seen image cut-off in External speaker settings • HPXWC-7363\[SFT_MPH][DisplayControl][HighContrast] Hover over disable toggle button, the border changes to different color under Desert, Dusk, Night sky contrast themes. • HPXWC-7227\[SFT_MPH][DisplayControl][HighContrast] Scheduler toggle button is not visible for Desert Contrast themes when toggle button is off. • HPXWC-7028\[HPX] It is better show highlight when user hover on "get details" & " view data collected" in PC device module. - Handle PR • HPXWC-7224\[SFT_MPH][AudioControl][HighContrast] In AudioControl module contrast themes not applied to background for half of the tab • HPXWC-7691\[AudioControl] Multi-streaming should be enabled by default. • HPXWC-7704\[SFT_MPH][DisplayControl][Accessibility] In LBL Scheduler page "Time" string is missing only when we select 225% scale. • HPXWC-7550\[SFT_MPH][DisplayControl][Accessibility][KeyboardNav] Tab selection border is not seen and not able to navigate to any other fields using tab/tab+shift button, when we hover over Turn-on/Turn-off dropdown container • HPXWC-5597\[Smartcam] Smartcam3 opens in the background on first launch if open from PC device (not Home). • HPXWC-7439\[AudioControl] Speaker Configuration UI doesn't consistent with its design | G19: 1. Home Page 2. Video Control - SmartCam 2 (if the system has SmartCam2 feature byte qj) - SmartCam 3.5.54.0 (if the system has SmartCam3 feature byte qM) 3. Audio Control 4. Display Control - display control driver: 5.1.0.060 5. Support 6. Settings 7. Audio Switch | I19: V | J19: V | K19: V | L19: V | M19: V | N19: V | O19: V | P19: V | Q19: V | R19: V | S19: V | Z19: V | AA19: V | AB19: V | AC19: V | AD19: V | AH19: V | AI19: V | AJ19: V | AK19: V | AL19: V | AM19: V | AN19: V | AO19: V | AP19: V | AQ19: V | AR19: V | AS19: V | AT19: V | AU19: V | AV19: V | AW19: V | BK19: V
A20: 45012 | B20: HPX | C20: Integration Build | D20: 25.22312.184.0.A.1 | E20: P014J4-B2P | F20: Main changes: Add SmartCam tooltips • HPXWC-7821\[Video] Integrate Smartcam into HPX v3.5.57 • HPXWC-7681\[HighContrast][PCDevice] The edit icon (Pencil) becomes completely invisible on • HPXWC-7706\[System Control][Native Library] Making Get & Set device API working • HPXWC-7224\[SFT_MPH][AudioControl][HighContrast] In AudioControl module contrast themes not applied to background for half of the tab • HPXWC-7691\[AudioControl] Multi-streaming should be enabled by default. • HPXWC-7704\[SFT_MPH][DisplayControl][Accessibility] In LBL Scheduler page "Time" string is missing only when we select 225% scale. • HPXWC-7550\[SFT_MPH][DisplayControl][Accessibility][KeyboardNav] Tab selection border is not seen and not able to navigate to any other fields using tab/tab+shift button, when we hover over Turn-on/Turn-off dropdown container • HPXWC-5597\[Smartcam] Smartcam3 opens in the background on first launch if open from PC device (not Home). • HPXWC-7439\[AudioControl] Speaker Configuration UI doesn't consistent with its design • HPXWC-7815\Update HP.SystemControl nuget to 1.0.1 in HPX • HPCMCT-1095\[Network Booster] Bandwidth chart issue • HPXWC-7677\Update the logic to check if the device supports consumer System Control | G20: 1. Home Page 2. Video Control - SmartCam 2 (if the system has SmartCam2 feature byte qj) - SmartCam 3.5.57.0 (if the system has SmartCam3 feature byte qM) 3. Audio Control 4. Display Control - display control driver: 5.1.0.058 5. Network Booster 6. System Control 7. Support 8. Settings 9. Audio Switch | I20: V | J20: V | K20: V | L20: V | M20: V | N20: V | O20: V | P20: V | Q20: V | R20: V | S20: V | Z20: V | AA20: V | AB20: V | AC20: V | AD20: V | AH20: V | AI20: V | AJ20: V | AK20: V | AL20: V | AM20: V | AN20: V | AO20: V | AP20: V | AQ20: V | AR20: V | AS20: V | AT20: V | AU20: V | AV20: V | AW20: V | BC20: V | BD20: V | BG20: V | BH20: V | BK20: V
A21: 45027 | B21: HPX | C21: Production Build | D21: 25.52314.112.0.A.1 | E21: P014J4-B2Q | F21: Main changes: For 23C2 platforms except Bopeep, Sammy, Oski, Tuffy, Willie, Herbie SmartCam123 is enabled • HPXWC-8199\[OOBE] Unable to see Firstuseflow • HPXWC-7751\[AudioSwitch] 'More Audio Control' link show in AudioSwitch even system doesn't have myHP audio control. • HPXWC-7906\[SFT_MPH][PenControl] Narrator is narrating the numbers in the UI as "Custom" • HPXWC-6413\[pen] Observations found in Accessibility testing. • HPXWC-7959\[Pen][highcontrast] Color is not applying for the tool tip pointer • HPXWC-7470\[HighContrast] Tooltip showing square shape for arrow in HighContrast mode. • HPXWC-7186\[SFT_MPH][SmartExp][HighContrast] Button text color is not changing for Dusk and Night sky themes • HPXWC-7225\[SFT_MPH][PenControl] When Serial/Product number is copied from the Header of Pen control, upon pasting the copied text is displayed as NA instead of original text. • HPXWC-7240\[SFT_MPH][DisplayControl][HighContrast] Brightness, Contrast and LBL Scheduler arrow icons are missing when we apply Aquatic and Night Sky High Contrast. | G21: 1. Home Page 2. Video Control - SmartCam 2 (if the system has SmartCam2 feature byte qj) - SmartCam 3.5.59.0 (if the system has SmartCam3 feature byte qM) 3. Audio Control 4. Display Control - display control driver: 5.1.0.060 5. Support 6. Settings 7. Audio Switch | I21: V | J21: V | K21: V | L21: V | M21: V | N21: V | O21: V | P21: V | Q21: V | R21: V | S21: V | Z21: V | AA21: V | AB21: V | AC21: V | AD21: V | AH21: V | AI21: V | AJ21: V | AK21: V | AL21: V | AM21: V | AN21: V | AO21: V | AP21: V | AQ21: V | AR21: V | AS21: V | AT21: V | AU21: V | AV21: V | AW21: V | BK21: V
A22: 45027 | B22: HPX | C22: Integration Build | D22: 25.22314.220.0.A.1 | E22: P014J4-B2R | F22: Main changes: For 23C2 Bopeep, Sammy, Oski, Tuffy, Willie, Herbie SmartCam123 is enabled • HPXWC-8199\[OOBE] Unable to see Firstuseflow • HPXWC-7751\[AudioSwitch] 'More Audio Control' link show in AudioSwitch even system doesn't have myHP audio control. • HPXWC-7470\[HighContrast] Tooltip showing square shape for arrow in HighContrast mode. • HPXWC-7240\[SFT_MPH][DisplayControl][HighContrast] Brightness, Contrast and LBL Scheduler arrow icons are missing when we apply Aquatic and Night Sky High Contrast. • HPXWC-8239\[System Control][UI] - Localization - Strings translation for title • HPCMCT-1141\Add 2 supported devices. • HPXWC-7591\[SystemControl] Native Base Tooltip Positioning, Hover , multiple label and close button Issue | G22: 1. Home Page 2. Video Control - SmartCam 2 (if the system has SmartCam2 feature byte qj) - SmartCam 3.5.59.0 (if the system has SmartCam3 feature byte qM) 3. Audio Control 4. Display Control - display control driver: 5.1.0.060 5. Network Booster 6. System Control 7. Support 8. Settings 9. Audio Switch | I22: V | J22: V | K22: V | L22: V | M22: V | N22: V | O22: V | P22: V | Q22: V | R22: V | S22: V | Z22: V | AA22: V | AB22: V | AC22: V | AD22: V | AH22: V | AI22: V | AJ22: V | AK22: V | AL22: V | AM22: V | AN22: V | AO22: V | AP22: V | AQ22: V | AR22: V | AS22: V | AT22: V | AU22: V | AV22: V | AW22: V | BC22: V | BD22: V | BG22: V | BH22: V | BK22: V
A23: 45034 | B23: HPX | C23: Production Build | D23: 25.52315.134.0.A.1 | E23: P014J4-B2T | F23: Main changes: For 23C2 platforms except Bopeep, Sammy, Oski, Tuffy, Willie, Herbie • HPXWC-8600\ [PCDevice] High CPU usage while idling in PC device page • HPXWC-8424\[HPX][Production] App stuck on StartUp Animation screen with latest Production Build • HPXWC-8503\[Core][HighContrast] My Hp app is getting crashed after switching the theme in High Contrast • HPXWC-7727\[Audio][Security] Known Vulnerability with .net version 4.7.2 • HPXWC-8386\[MyAccount] Profile icon is missing • HPXWC-6799\[SFT_MPH][DisplayControl][Accessibility] Placeholder is not applied properly for brightness and contrast slider while we navigate through TAB • HPXWC-7680\[PCDevice][HighContrast] Hover color not getting applied in High Contrast Mode on Breadcrumb • HPXWC-4654\[HomePage] Cannot set dynamic height in JWebs • HPXWC-6039\SIO2169694 - It doesn't respond by clicking Output speaker icon when turn off mute with headset plug out and plug in • HPXWC-8161\[AudioControl][AudioSwitch] Hitting more audio link from system tray has issue with breadcrumb title • HPXWC-8247\[PC Device][AUID] Navigate to any action tiles from pc device AUID changed with language • HPXWC-7107\[HPX][DarkMode] Country in drop-down list is not visible in Registration page when change system colour to dark mode. • HPXWC-7414\[SFT_MPH][AudioControl][HighContrast] On Equalizer tab Color contrast themes are not applied properly | G23: 1. Home Page 2. Video Control - SmartCam 2 (if the system has SmartCam2 feature byte qj) - SmartCam 3.5.59.0 (if the system has SmartCam3 feature byte qM) 3. Audio Control 4. Display Control - display control driver: 5.1.0.060 5. Support 6. Settings 7. Audio Switch | I23: V | J23: V | K23: V | L23: V | M23: V | N23: V | O23: V | P23: V | Q23: V | R23: V | S23: V | Z23: V | AA23: V | AB23: V | AC23: V | AD23: V | AH23: V | AI23: V | AJ23: V | AK23: V | AL23: V | AM23: V | AN23: V | AO23: V | AP23: V | AQ23: V | AR23: V | AS23: V | AT23: V | AU23: V | AV23: V | AW23: V | BK23: V
A24: 45034 | B24: HPX | C24: Integration Build | D24: 25.22315.247.0.A.1 | E24: P014J4-B2U | F24: Main changes: For 23C2 Bopeep, Sammy, Oski, Tuffy, Willie, Herbie • HPXWC-8645\ [Video-42] Deliver SmartCam v3.2304.64 for HPX integration 2023.04.B • HPXWC-8600\ [PCDevice] High CPU usage while idling in PC device page • HPXWC-8549\[PCDevice][AudioControl] 10 band EQ sliders dragging issue • HPXWC-8048\[HPAC] Desktop extension callback is not registered and updating • HPXWC-8574\ [SFT_MPH][DisplayControl] Contrast slider tip slightly move to right side when we renavigate to Display Control module after relaunch HPX application or from PC device page. • HPXWC-8274\[RGB][DarkMode] Display page needs to be changed for Dark Mode • HPXWC-6658\SIO2172289 - [SIT][Zonin][HPX0.5_OTA] HPPV will not reminds you 'Camera being used by another application' when launch video control at the second time after open the camera app first. • HPXWC-8469\ [Display][UI]Localization • HPXWC-8251\[Display][UI][Display][UI] - Dark mode support for PCDisplay | G24: 1. Home Page 2. Video Control - SmartCam 2 (if the system has SmartCam2 feature byte qj) - SmartCam 3.2304.64 (if the system has SmartCam3 feature byte qM) 3. Audio Control 4. Display Control - display control driver: 5.1.0.060 5. Network Booster 6. System Control 7. Support 8. Settings 9. Audio Switch | I24: V | J24: V | K24: V | L24: V | M24: V | N24: V | O24: V | P24: V | Q24: V | R24: V | S24: V | Z24: V | AA24: V | AB24: V | AC24: V | AD24: V | AH24: V | AI24: V | AJ24: V | AK24: V | AL24: V | AM24: V | AN24: V | AO24: V | AP24: V | AQ24: V | AR24: V | AS24: V | AT24: V | AU24: V | AV24: V | AW24: V | BC24: V | BD24: V | BG24: V | BH24: V | BK24: V
A25: 45041 | B25: HPX | C25: Production Build | D25: 25.52316.154.0.A.1 | E25: P014J4-B2V | F25: Main changes: For: 23C2 platforms except Bopeep, Sammy, Oski, Tuffy, Willie, Herbie 2305 Softroll platforms Updated SmartCam to 3.2304.68.21904 • HPXWC-8959\ [CGQA][FirstUse]"Oh something went wrong" error message is displayed after HP registration successfully. • HPXWC-7901\ [NPS][CGQA] If "share your feedback" toggle is turned off then NPS should not display during first launch • HPXWC-7649\ [SFT_MPH][AudioControl] 3.5 mm headset crash/Multi streaming/Device plug unplug • HPXWC-8648\ [CoreNav] myHP not able to drag and slide from the top bar after loaded completely • HPXWC-8538\ [Settings][NotificationsTab] Narrator is not reading Content in Notification Tab • HPXWC-7625\ [SFT_MPH][EIT][Bell] Notification count still shows on the taskbar, while the user sign-out with new notification unread even post relaunching. • HPXWC-8921\ [RGBKB] Breathing effect interval is too long • HPXWC-8536\ [Settings][Privacy]Narrator is not reading the content in Privacy tab in Settings page • HPXWC-8554\ [Offline][HighContrast][Accessibility] Set ‘text size’ to maximum and change High contrast theme, the offline banner is not displayed normally • HPXWC-6918\ SIO2169154: [DisplayControl] Display Control is not localized in FR Language • HPXWC-8198\ [FirstUseFlow] If all consents are Unknown not able to see Registration page. • HPXWC-7362\ [SFT_MPH][HomePage][HighContrast] Home Page background cutoff observed after applying contrast themes. • HPXWC-6597\ [Accessibility][HighContrast] We cannot see the menu when set the theme is Aquatic mode • HPXWC-8704\ Narrator is reading Bell Icon Incorrectly | G25: 1. Home Page 2. Video Control - SmartCam 2 (if the system has SmartCam2 feature byte qj) - SmartCam 3.2304.68.21904 (if the system has SmartCam3 feature byte qM) 3. Audio Control 4. Display Control - display control driver: 5.1.0.060 5. Support 6. Settings 7. Audio Switch | I25: V | J25: V | K25: V | L25: V | M25: V | N25: V | O25: V | P25: V | R25: V | S25: V | Z25: V | AA25: V | AB25: V | AC25: V | AD25: V | AH25: V | AI25: V | AJ25: V | AK25: V | AL25: V | AM25: V | AN25: V | AO25: V | AP25: V | AQ25: V | AR25: V | AS25: V | AT25: V | AU25: V | AV25: V | AW25: V | BK25: V
