Workbook
Name DATA: #REF!

Sheet Module Owners
A1: myHP
A2: Module/Scope | B2: Assign to Component | C2: Owner
A3: Core/Generic for consumer | B3: myHP | C3: Lee, Su-Hau <su-hau.lee1@hp.com>; Huang, Alex <alex.huang@hp.com>
A4: Core/Generic for CMIT | B4: myHP for CMIT | C4: Lee, Su-Hau <su-hau.lee1@hp.com>; Huang, Alex <alex.huang@hp.com>
A5: Consumer Audio Controls | B5: myHP module_Audio Control | C5: Huang, Alex <alex.huang@hp.com>
A6: Consumer myHP Audio Switch | B6: myHP module_Audio Switch | C6: Huang, Alex <alex.huang@hp.com>
A7: Consumer Display Control | B7: myHP module_Display Control | C7: Wang, Vicky (Consumer SWPM) <vicky.wang3@hp.com>
A8: CMIT Programmable Key | B8: myHP module_Programmable Key | C8: Narayanappa, Geetha (CW-Mphasis - SFT) <geetha.narayanappa1@hp.com>; Armstrong, Sridhar (CW) <sridhar.armstrong@hp.com>
A9: SmartCam 1, SmartCam 2 | B9: myHP module_SmartCam | C9: Hsiao, Steven (CW-CW DSAI) <steven.hsiao@hp.com>, Wang, Vicky (Consumer SWPM) <vicky.wang3@hp.com>
A10: SmartCam 3 | B10: myHP module_SmartCam3 | C10: Hsiao, Steven (CW-CW DSAI) <steven.hsiao@hp.com>, Wang, Vicky (Consumer SWPM) <vicky.wang3@hp.com>
A11: CMIT IC1.0 | B11: myHP module_IC1.0 | C11: Armstrong, Sridhar (CW) <sridhar.armstrong@hp.com>
A12: CMIT Smart Experiences | B12: myHP module_Smart Experiences | C12: Guru, Anand <anand.guru@hp.com>
A13: CMIT Audio Controls | B13: myHP module_CMITAudio | C13: Jagdale, Shailesh (CW-Capgemini -WW PM) <shailesh.jagdale@hp.com>
A15: HPX
A16: Module/Scope | B16: Assign to Component | C16: Owner
A17: Core/Generic for consumer | B17: HPX | C17: Lee, Su-Hau <su-hau.lee1@hp.com>; Huang, Alex <alex.huang@hp.com>
A18: Core/Generic for CMIT | B18: HPX for CMIT | C18: Lee, Su-Hau <su-hau.lee1@hp.com>; Huang, Alex <alex.huang@hp.com>
A19: Consumer Audio Controls | B19: HPX_Audio Control | C19: Huang, Alex <alex.huang@hp.com> (NB: Katherine Wei DT: Ken Chiu)
A20: Consumer myHP Audio Switch | B20: HPX_Audio Switch | C20: Huang, Alex <alex.huang@hp.com>
A21: Consumer Display Control | B21: HPX_Display Control | C21: JADHAV, SANJEEV (CW) <sanjeev.jadhav@hp.com> (Wang, Vicky (Consumer SWPM) <vicky.wang3@hp.com>)
A22: CMIT Programmable Key | B22: HPX_Programmable Key | C22: Narayanappa, Geetha (CW-Mphasis - SFT) <geetha.narayanappa1@hp.com>; Armstrong, Sridhar (CW) <sridhar.armstrong@hp.com>
A23: SmartCam 1, SmartCam 2 | B23: HPX_SmartCam 2.0 | C23: Hsiao, Steven (CW-CW DSAI) <steven.hsiao@hp.com> (Wang, Vicky (Consumer SWPM) <vicky.wang3@hp.com>)
A24: SmartCam 3.5 | B24: HPX_SmartCam3.5 | C24: Hsiao, Steven (CW-CW DSAI) <steven.hsiao@hp.com> (Wang, Vicky (Consumer SWPM) <vicky.wang3@hp.com>)
A25: CMIT Smart Experiences | B25: HPX_Smart Experiences | C25: Narayanappa, Geetha (CW-Mphasis - SFT) <geetha.narayanappa1@hp.com>
A26: Pen Control (Consumer) | B26: HPX_Pen Control | C26: Lin, Makayla <makaylal@hp.com> (Patel, Jay (CW) <jay.patel@hp.com>)
A27: 5G | B27: HPX_5G | C27: Huang, Alex <alex.huang@hp.com>
... A37: System Control (Consumer) | B37: HPX_System Control | C37: Tsai, TC CPS SE <tc.tsai@hp.com> (Tsai, Josette <josette.tsai@hp.com>)
A38: System Control (Commercial) | B38: HPX_System Control_CMIT
A39: Battery Manager (Commercial) | B39: HPX_Battery Manager_CMIT
A40: Wi-Fi Sharing (Consumer) | B40: HPX_WiFi Sharing | C40: Tsai, Josette <josette.tsai@hp.com>

Sheet HPX Version
H1: Main Feature | I1: Auto Launch | J1: First Use Flow | K1: Audio Switch (Appears in taskband) | L1: Home Page | M1: Support | N1: Audio Control | Y1: Video Control | AR1: Presence Detection | AT1: Network Booster | AV1: HP Programmable Key | AX1: System Control | AZ1: Settings | BA1: Pen | BB1: Battery Manager | BC1: Screen Time | BD1: Screen Distance | BE1: Gesture | BF1: Docking | BG1: Energy Consumption | BH1: Camera and presence detection | BI1: HP GO | BJ1: Smart Displays | BK1: Look To Move
H2: Sub-Feature | O2: Audio Levels | P2: Noise Cancellation/ AI Noise Removal | Q2: Equalizer | R2: Speaker Swap | S2: Speaker Configuration (only in Tower PC) | T2: Dynamic Audio | U2: Audio Personalization | V2: AI Dynamic Spatial effect | W2: Studio Recording Mode | X2: Restore Default | Z2: Feature Byte | AA2: Auto Frame | AB2: Low Light | AC2: Backlight | AD2: Background Blur/Image | AE2: Auto and Manual Keystone | AF2: Be-Right-Back | AG2: Video and Image Capture/PDF | AH2: Live Stream | AI2: Rotate/Zoom/Pan | AJ2: Output Resolution | AK2: Skin Color Correction | AL2: Appearance Filter | AM2: Presence Share | AN2: Multicamera (Mixer tab) | AO2: Auto Camera Select | AP2: Gallery Mode | AQ2: Anti-Flicker (Selected platforms. Open MS Camera app and check Video Settings. If Flicker reduction is supported, Anti-flicker will be shown in SmartCam) | AR2: Privacy Alert | AS2: Auto Screen Dimming | AU2: Mode switch (bandwidth prioritization) - non Evo sku only | AW2: App, Website, Folder, File Launch | AY2: Smart Resource Optimizer
A3: Date | B3: Component | C3: Build Type | D3: Version | E3: Part Number(IRS) | F3: Release Notes | G3: Modules Enabled
A4: 44908 | B4: HPX for CMIT | C4: Dev Build | D4: 25.12249.42.0.A.1 | E4: P014C9-B2A | F4: For 2023 NPI, CFR on or after 1/3 platforms Changes: First HPX Dev Track build Known issues: 1. HPX doesn't work in offline mode yet 2. HP ID (Sign In) only works in HP network 3. The Welcome page only works in HP network 4. The Support page only works in HP network 5. SmartCam2 preview camera is always in "Please wait" state | G4: 1. Welcome Page 2. Video Control - SmartCam 2 (if the system has SmartCam2 feature byte qj) - SmartCam 3.5.14.0 (if the system has SmartCam3 feature byte qM) 3. HP Programmable Key 4. Privacy alert 5. Auto Screen Dimming 6. Support 7. Settings | I4: V | J4: V | L4: V | M4: V | Y4: V | Z4: V | AA4: V | AB4: V | AC4: V | AD4: V | AE4: V | AF4: V | AG4: V | AH4: V | AI4: V | AJ4: V | AK4: V | AL4: V | AM4: V | AN4: V | AO4: V | AR4: V | AS4: V | AV4: V | AW4: V | AZ4: V
A5: 44914 | B5: HPX for CMIT | C5: Dev Build | D5: 25.12251.139.0.A.1 | E5: P014C9-B2B | F5: For 2023 NPI, CFR on or after 1/3 platforms Main changes: • Update SmartCam to 3.5.20.0 • Redundant control cards will not show • Sound Calibration removed • Performance enhancement • Localization fixes • Fixed HPX shows white screen when launch in offline mode Known issues: 1. HP ID (Sign In) only works in HP network 2. The Support page content only shows in HP network 3. SmartCam2 preview camera is always in "Please wait" state | G5: 1. Welcome Page 2. Video Control - SmartCam 2 (if the system has SmartCam2 feature byte qj) - SmartCam 3.5.20.0 (if the system has SmartCam3 feature byte qM) 3. HP Programmable Key 4. Privacy alert 5. Auto Screen Dimming 6. Support 7. Settings | I5: V | J5: V | L5: V | M5: V | Y5: V | Z5: V | AA5: V | AB5: V | AC5: V | AD5: V | AE5: V | AF5: V | AG5: V | AH5: V | AI5: V | AJ5: V | AK5: V | AL5: V | AM5: V | AN5: V | AO5: V | AR5: V | AS5: V | AV5: V | AW5: V | AZ5: V
A6: 44932 | B6: HPX for CMIT | C6: ITG Build | D6: 25.22301.11.0.A.1 | E6: P014C9-B2C | F6: For 2023 NPI, CFR on or after 1/10 platforms Main changes: - Update SmartCam to 3.5.26.0 - HPXWC-5009\Flyout menu in Arabic language appears in wrong side (they should appear in right side) - HPXWC-5126\[Home Page] PC Control Section does not render on Home page - HPXWC-5133\To enable for getting all the keys from the AKV - HPXWC-3399\[CGQA] Thank you! screen UI is not same as design specification - HPXWC-5062\[HPX][L10N] HP registration page not localized with some languages - HPXWC-5027\[SFT_MPH][OTA][VideoControl] Video control module is not visible in HPX V.25.12251.154.0 - Removed Privacy Settings in First Use Flow - Removed Mouse from menu Known issues: 1. HP ID (Sign In) only works in HP network 2. The Support page content only shows in HP network 3. SmartCam2 preview camera is always in "Please wait" state | G6: 1. Welcome Page 2. Video Control - SmartCam 2 (if the system has SmartCam2 feature byte qj) - SmartCam 3.5.26.0 (if the system has SmartCam3 feature byte qM) 3. HP Programmable Key 4. Privacy alert 5. Auto Screen Dimming 6. Support 7. Settings | I6: V | J6: V | L6: V | M6: V | Y6: V | Z6: V | AA6: V | AB6: V | AC6: V | AD6: V | AE6: V | AF6: V | AG6: V | AH6: V | AI6: V | AJ6: V | AK6: V | AL6: V | AM6: V | AN6: V | AO6: V | AR6: V | AS6: V | AV6: V | AW6: V | AZ6: V
A7: 44935 | B7: HPX for CMIT | C7: ITG Build | D7: 25.22302.22.0.A.1 | E7: P014C9-B2D | F7: For 2023 NPI, CFR on or after 1/10 platforms Main changes: - HPXWC-5281\Update SmartCam Nuget package to 3.5.30 - HPXWC-5009\Flyout menu in Arabic language appears in wrong side (they should appear in right side) - HPXWC-5126\[Home Page] PC Control Section does not render on Home page - HPXWC-5133\To enable for getting all the keys from the AKV - HPXWC-3399\[CGQA] Thank you! screen UI is not same as design specification - HPXWC-5062\[HPX][L10N] HP registration page not localized with some languages - HPXWC-5027\[SFT_MPH][OTA][VideoControl] Video control module is not visible in HPX V.25.12251.154.0 - Removed Privacy Settings in First Use Flow - Removed Mouse from menu - HPXWC-5286\[London]"Programmable key" not able to launch from "Home page". - HPXWC-4923\Update translation files to be in line with the latest spec - HPXWC-4741\SIO2161423 - [CommercialPC:AsteroidsR/GalaxianR/PacmanR] Some words not localization in HPX on non-English image. - HPXWC-5072\SIO2163859 - Prompt text has "& apos;" in Programmable key in French image - HPXWC-4947\ SIO2162928 - UI show black page when launch HPX without internet Known issues: 1. HP ID (Sign In) only works in HP network 2. The Support page content only shows in HP network 3. SmartCam2 preview camera is always in "Please wait" state | G7: 1. Welcome Page 2. Video Control - SmartCam 2 (if the system has SmartCam2 feature byte qj) - SmartCam 3.5.30.0 (if the system has SmartCam3 feature byte qM) 3. HP Programmable Key 4. Privacy alert 5. Auto Screen Dimming 6. Keyboard 7. Support 8. Settings | I7: V | J7: V | L7: V | M7: V | Y7: V | Z7: V | AA7: V | AB7: V | AC7: V | AD7: V | AE7: V | AF7: V | AG7: V | AH7: V | AI7: V | AJ7: V | AK7: V | AL7: V | AM7: V | AN7: V | AO7: V | AR7: V | AS7: V | AV7: V | AW7: V | AZ7: V
A8: 44939 | B8: HPX for CMIT | C8: ITG Build | D8: 25.22302.36.0.A.1 | E8: P014C9-B2E | F8: For 2023 NPI, CFR on or after 1/10 platforms Main changes: Keyboard feature removed Fixed SmartCam2 camera preview always show "Please wait" Sign In/Welcome/Support pages can now work in non-HP network • HPXSUP-687\The string "Support" in left navigation isn't translated for id-ID language. • HPXWC-4276\[SFT_MPH][PCDevice] Text cut-off and overlapping observed when increasing text size to maximum • HPXWC-5121\Integrate Localizations and Replace HPDC.dll file • HPXWC-5160\[SFT_MPH][SmartExp][L10N] Extra string for "30 minutes" in Romanian-RO language • HPXWC-5200\[SmartExp]: Loalization support for consent dialog • HPXWC-4982\SIO2162441 - [NB][QTA][SCIT-NPI] Window will auto exit when click "Manage Options" during HPX first use flow • HPXWC-4957\ [SFT_MPH][Registration][L10N] Registration Page is missing in Hebrew Language • HPXWC-5061\[Setup] HPX will crash when first launch with HE-IL language • HPXWC-4864\[SFT_MPH][Registration] Checkbox UI is not matching with figma design • HPXWC-5078\ [SFT-MPH][OTA][Video] Camera preview is greyed out when we click on Video Control module (SC2) • HPXWC-5392\ Add deep link for sublevel items • HPXWC-5240\ Keyboard module seems to be not under any feature switch • HPXSUP-716\ [Support] Support page still not loading, keep flashing with latest ITG build, after implemented the production link. • HPXSUP-623\ [Support home page]- The support home page hangs on loading page • HPXSUP-620\ [Offline] - The Device name/SN/PN are missing. • HPXSUP-625\ [Offline] - No translation on offline page • HPXSUP-628\ [Offline] - We still show up Phone card in offline even though the location isn't US/CA • HPXSUP-675\ [Offline] - Support icon and the string are too close together in latest build • HPXSUP-395\ [Offlline -Accessibility] - Serval Failures when run Automated checks • HPXSUP-679\ [Custom protocol &Hotkey] The support page always hangs when enter the myhp://support/device in RUN window • HPXSUP-585\ [Offline]-The contents of the call card and web card on the offline page are not aligned • HPXSUP-586\ [Offline]-When zooming out HPX window, the scroll bar is not as expected on offline page. • HPXSUP-616\ [Offline] - The offline UI is different from Mockup • HPXWC-5334\ [SFT_MPH][SmartExp] Privacy Alert page is not opening on clicking toast notification • HPXWC-5072\ SIO2163859 - Prompt text has "& apos;" in Programmable key in French image | G8: 1. Welcome Page 2. Video Control - SmartCam 2 (if the system has SmartCam2 feature byte qj) - SmartCam 3.5.30.0 (if the system has SmartCam3 feature byte qM) 3. HP Programmable Key 4. Privacy alert 5. Auto Screen Dimming 6. Support 7. Settings | I8: V | J8: V | L8: V | M8: V | Y8: V | Z8: V | AA8: V | AB8: V | AC8: V | AD8: V | AE8: V | AF8: V | AG8: V | AH8: V | AI8: V | AJ8: V | AK8: V | AL8: V | AM8: V | AN8: V | AO8: V | AR8: V | AS8: V | AV8: V | AW8: V | AZ8: V
A9: 44942 | B9: HPX for CMIT | C9: Integration Build | D9: 25.22303.43.0.A.1 | E9: P014C9-B2F | F9: For 2023 NPI, CFR on or after 1/10 platforms Main changes: Update Smartcam 3 to 3.5.37.0 Keyboard feature removed Fixed SmartCam2 camera preview always show "Please wait" Sign In/Welcome/Support pages can now work in non-HP network • HPXSUP-687\The string "Support" in left navigation isn't translated for id-ID language. • HPXWC-4276\[SFT_MPH][PCDevice] Text cut-off and overlapping observed when increasing text size to maximum • HPXWC-5121\Integrate Localizations and Replace HPDC.dll file • HPXWC-5160\[SFT_MPH][SmartExp][L10N] Extra string for "30 minutes" in Romanian-RO language • HPXWC-5200\[SmartExp]: Loalization support for consent dialog • HPXWC-4982\SIO2162441 - [NB][QTA][SCIT-NPI] Window will auto exit when click "Manage Options" during HPX first use flow • HPXWC-4957\ [SFT_MPH][Registration][L10N] Registration Page is missing in Hebrew Language • HPXWC-5061\[Setup] HPX will crash when first launch with HE-IL language • HPXWC-4864\[SFT_MPH][Registration] Checkbox UI is not matching with figma design • HPXWC-5078\ [SFT-MPH][OTA][Video] Camera preview is greyed out when we click on Video Control module (SC2) • HPXWC-5392\ Add deep link for sublevel items • HPXWC-5240\ Keyboard module seems to be not under any feature switch • HPXSUP-716\ [Support] Support page still not loading, keep flashing with latest ITG build, after implemented the production link. • HPXSUP-623\ [Support home page]- The support home page hangs on loading page • HPXSUP-620\ [Offline] - The Device name/SN/PN are missing. • HPXSUP-625\ [Offline] - No translation on offline page • HPXSUP-628\ [Offline] - We still show up Phone card in offline even though the location isn't US/CA • HPXSUP-675\ [Offline] - Support icon and the string are too close together in latest build • HPXSUP-395\ [Offlline -Accessibility] - Serval Failures when run Automated checks • HPXSUP-679\ [Custom protocol &Hotkey] The support page always hangs when enter the myhp://support/device in RUN window • HPXSUP-585\ [Offline]-The contents of the call card and web card on the offline page are not aligned • HPXSUP-586\ [Offline]-When zooming out HPX window, the scroll bar is not as expected on offline page. • HPXSUP-616\ [Offline] - The offline UI is different from Mockup • HPXWC-5334\ [SFT_MPH][SmartExp] Privacy Alert page is not opening on clicking toast notification • HPXWC-5072\ SIO2163859 - Prompt text has "& apos;" in Programmable key in French image • HPXWC-5406\ [PCVideo] Show 'start HP Present Video failed' error when trying to launch Video control. • Update Smartcam 3 to 3.5.37.0 • HPXWC-4895\ SIO2162130 - [Pen] Pen Control list under HPX Devices, but HP Pen Settings already installed. • HPXWC-5231\ [Localization] Chinese dialects appear in the wrong dialect • HPXWC-5334\ [SFT_MPH][SmartExp] Privacy Alert page is not opening on clicking toast notification • HPXWC-5315\ [SFT_MPH][RGBKB] "Restore setting" button looks different from figma UI • HPXWC-4931\ State of hamburger menu is not changing in left navigation on hover o HPXWC-5142\ Create a template for System Control in HPX o HPXWC-5417\ [EIT] Even after logging out, the screen remains in the logged-in state. • HPXWC-5296\ [Core] "Something went wrong" error message always pop up on some machines | G9: 1. Home Page 2. Video Control - SmartCam 2 (if the system has SmartCam2 feature byte qj) - SmartCam 3.5.37.0 (if the system has SmartCam3 feature byte qM) 3. HP Programmable Key 4. Privacy alert 5. Auto Screen Dimming 6. Support 7. Settings | I9: V | J9: V | L9: V | M9: V | Y9: V | Z9: V | AA9: V | AB9: V | AC9: V | AD9: V | AE9: V | AF9: V | AG9: V | AH9: V | AI9: V | AJ9: V | AK9: V | AL9: V | AM9: V | AN9: V | AO9: V | AR9: V | AS9: V | AV9: V | AW9: V | AZ9: V
A10: 44954 | B10: HPX for CMIT | C10: Staging Build | D10: 25.42304.147.0.A.1 | E10: P014C9-B2G | F10: For 2023 NPI, CFR on or after 1/10 platforms Main changes: Update SmartCam to 3.5.39.0 • HPXWC-4499\ Left navigation should be reflected when device name is updated in PCDevicePage • HPXSUP-749\ Update ClientID to HPXWin for warranty API • HPXWC-4967\ [SFT_MPH][Services]intermittently on clicking on "go to myAccount" in the flyout shows an error • HPXWC-2811\ [CGQA][FirstUse] Font size/color/style are not matching same as design specification for first use flow all screens. • HPXWC-5477\ [SmartExp][PPR] Incorrect Padding Inside the Card • HPXWC-4889\ First use using oversize (and duplicate) PNGs instead of JPG assets for photo images • HPXSUP-750\ [Localization]-The support page shows Simplified Chinese on zh-TW machine • HPXWC-5432\ [SFT_MPH][OTA] PC Device warranty status is mismatch with Support page warranty status • HPXWC-5177\ [UI][Truncation] Truncated text needs an on hover flyout that displays the full string to the user • HPXWC-4249\ [SFT_MPH][Core] Battery life test result exceeding more than 0.01 threshold value for HPX application. • HPXWC-5541\Smartexperiences using oversize PNGs for photo content • HPXWC-4142\[PPR] HP Registration country dropdown text font should match with country dropdown values font. • HPXWC-5413\[HomePg] Application crashes from Interstitial pages • HPXWC-5567\[SFT_MPH][Core] PC Device UI shows mostly empty on changing back the High contrast to None. • HPXWC-5703\ [Core][Performance] Memory leak observed upon clicking on different module from left navigation panel • HPXWC-5704\ [Core] Webview instances are never destroyed, eventually leading to memory full/crash • HPXWC-5722\ [SFT_MPH][SmartExp] Snooze Duration Dropdown box is not visible in Privacy Alert Page • HPXWC-5550\ SIO2167393 - [SIT][SWT-SW][CZN-H][HPX0.5_OTA]"Connect" button show cut off when offline in myHP\home page on AB2 image. • HPXWC-5750\ [Settings] Change Copyright to 2023 | G10: 1. Home Page 2. Video Control - SmartCam 2 (if the system has SmartCam2 feature byte qj) - SmartCam 3.5.39.0 (if the system has SmartCam3 feature byte qM) 3. HP Programmable Key 4. Privacy alert 5. Auto Screen Dimming 6. Support 7. Settings | I10: V | J10: V | L10: V | M10: V | Y10: V | Z10: V | AA10: V | AB10: V | AC10: V | AD10: V | AE10: V | AF10: V | AG10: V | AH10: V | AI10: V | AJ10: V | AK10: V | AL10: V | AM10: V | AN10: V | AO10: V | AR10: V | AS10: V | AV10: V | AW10: V | AZ10: V
A11: 44957 | B11: HPX for CMIT | C11: Staging Build | D11: 25.42305.150.0.A.1 | E11: P014C9-B2H | F11: For 2023 NPI, CFR on or after 1/10 platforms Main changes: Staging Build Update SmartCam to 3.5.39.0 HPXWC-5815\[myAccount] HPX closed when we click 'go to my account' in ITG build. HPXWC-5184\[SFT_MPH][OTA][Settings] Intermittently HPX version is displaying as NULL HPXWC-5772\[UI] Icons are not properly visible in some resolutions. HPXWC-5752\[PPR] Square corner with different color near rounded corner HPXWC-4978\[SFT_MPH][OTA] Text cut-off is seen when we minimize the Privacy Settings page. HPXWC-5749\[PCDevice] Warranty status icon for "Unknown" mismatch with figma on ultron laptop HPXWC-5162\[SFT_MPH][DisplayControl] Text box cutoff seen when we navigate using tab button HPXWC-5799\[DevOps] 0 version bulk script needs to be skipped when there is not file under ./change folder HPXWC-5677\[CGQA] myHP icon is missing in internet connection screen title-bar. HPXWC-5470\[Core] LocalizationJplugin is not providing 5 character locale HPXWC-5816\[Support][Deeplink] Support card on PC Device page takes you to top level Support module HPXWC-5797\[Pen] Feature-specific (Pen? Wacom.ISD.SettingsClient.dll) binary embedded in the Shell (UWP or DesktopExtension) HPXWC-5552\[PCVideo] HPPV screen can not open again when restart PC then launch HPPV screen again HPXWC-5735\[Analytics] PC Mouse generating unnecessary events on hover HPXWC-5355\[AudioControl] Sound does not change when increase or decrease the ft and db value when click play test button HPXWC-5474\[HPPK][PPR] Modal window: Application, header typography is incorrect | G11: 1. Home Page 2. Video Control - SmartCam 2 (if the system has SmartCam2 feature byte qj) - SmartCam 3.5.39.0 (if the system has SmartCam3 feature byte qM) 3. HP Programmable Key 4. Privacy alert 5. Auto Screen Dimming 6. Support 7. Settings | I11: V | J11: V | L11: V | M11: V | Y11: V | Z11: V | AA11: V | AB11: V | AC11: V | AD11: V | AE11: V | AF11: V | AG11: V | AH11: V | AI11: V | AJ11: V | AK11: V | AL11: V | AM11: V | AN11: V | AO11: V | AR11: V | AS11: V | AV11: V | AW11: V | AZ11: V
A12: 44963 | B12: HPX for CMIT | C12: Staging Build | D12: 25.42305.5.0.A.1 | E12: P014C9-B2J | F12: For 2023 NPI, CFR on or after 1/10 platforms Main changes: Note: This is still a staging build. We are still waiting for a production build that will be used for shipping. Fixed issues: SIO2167712 - [SIT][FIT-MM][Zonin][ADL-S][HPX0.5_OTA] There is no "Audio control" item and "Video control" item in Device/PC device page after launch the HPX.(AB2&ABJ) SIO2169145 - [SIT][SWT-SW][Montes-ADL][HPX0.5_OTA] There is no smartcam in HPX after OTA upgrade from MS store. (HPX v25.42305.150.0) SIO2169133 - [SIT][SWT-SW][Contino][Barcelo][HPX0.5_OTA]There is no smartcam in HPX after OTA upgrade from MS store. (HPX v25.42305.150.0) SIO2169215 - [SIT][SWT-SW][ADL][HPX0.5_OTA]There is no Video Control in myHP(HPX). SIO2169158 - [SIT][SWT-SW][BCL-R][Win11][PV1][HPX0.5_OTA] HPX(myHP) Version show 25.22304.113.0 in About page but should be 25.42305.150.0 (F/R:1/2 units) HPXSUP-767\[OCChat] Chat Page will be loading sometimes when change country frequently. HPXWC-5926\[Home] Welcome Banner should not have comma when User is signed in to the account HPXWC-4305\[SFT_MPH][CoreNav][Accessibility] Narrator fails to read expected action when hamburger menu is opened/closed. myHP icon read as custom HPXWC-6015\[Home Page] Set new static height for Recommended for you section of Home page HPXWC-5563\[Accessibility] There is no response when using Enter key to open notification and profile icons. HPXWC-5764\[Communications]In Spanish-Spain Language, Mismatch in toggle alignment in Settings-Notifications page HPXWC-5763\[Communications]In Catalan - Ca Language, Mismatch in toggle alignment in Settings-Notifications page HPXWC-4829\[HPX 0.5] Icon: PC Unselected Device icon is incorrect HPXWC-4828\[HPX 0.5] Icon: Devices icon and color is incorrect | G12: 1. Home Page 2. Video Control - SmartCam 2 (if the system has SmartCam2 feature byte qj) - SmartCam 3.5.39.0 (if the system has SmartCam3 feature byte qM) 3. HP Programmable Key 4. Privacy alert 5. Auto Screen Dimming 6. Support 7. Settings | I12: V | J12: V | L12: V | M12: V | Y12: V | Z12: V | AA12: V | AB12: V | AC12: V | AD12: V | AE12: V | AF12: V | AG12: V | AH12: V | AI12: V | AJ12: V | AK12: V | AL12: V | AM12: V | AN12: V | AO12: V | AR12: V | AS12: V | AV12: V | AW12: V | AZ12: V
A13: 44967 | B13: HPX for CMIT | C13: Staging Build | D13: 25.42306.11.0.A.1 | E13: P014C9-B2K | F13: For 2023 NPI, CFR on or after 1/30 platforms Main changes: Note: This is still a staging build. We are still waiting for a production build that will be used for shipping. Fixed issues since 25.42306.8.0 : - HPXWC-5868\ [CGQA] HP icon is not properly visible for some resolutions in HP Registration and privacy policy screens. - HPXWC-3926\ [CGQA] Privacy-Policy screen UI is not matching with design specification. - HPXWC-5806\ [Display] Feature-specific (DisplayControl? HPDC.dll) binary embedded in the Shell (UWP or DesktopExtension) - HPXWC-5492\ [Pen] Pen Control not visible even if standalone Pen Settings App is not present in device - HPXWC-6032\ [AudioControl][DynamicAudio] Dynamic Audio should not show up in side panel on Nittany - HPXWC-5939\ [PCDevice] "Get Details" for warranty info is seen after HPX application restarts. - HPXSUP-939\ PCDevice - image borders are black SVG methone images - HPXWC-5668\ [RGBKB] Code optimization in Effects Fixed issues since 25.42306.9.0 : - HPXWC-6005\ [Core] Home page Programmable Key icon is incorrect on HP1 platforms - HPXWC-5603\ SIO2167745 - [SIT][SWT-SW][22H2-SFR][Blizzard_L] The function is lost on 4ch and 5.1ch of speaker configuration with support devices - HPXWC-5547\ SIO2167525 - [NB][Roc][Kraken][CFR][QTA][SCIT-NPI] Navigation auto open and can not use the myHP Home page - HPXWC-5860\ [PCDevice] The Warranty icon for in-warranty system is not correct after clicking on Get Details - HPXWC-5755\[Audio][PPR] Sound calibration dropdown menu should use updated style - HPXWC-5862\[SFT_MPH][SmartExp][L10N] 'HP Privacy link' text cutoff in some languages on dialog box Fixed issues in 25.42306.11.0 : - HPXWC-5495\[SFT_MPH][Core] Resize window, see movement and adjustment of the UI elements in accordance to window size - HPXWC-6180\SIO2167901 - [NB][Kraken][Roc] The "<--" button overlaps "x" close button in HPX/Home/Recommended for you on ABV image. - HPXWC-5653\SIO2167554 - [NB][Roc][Kraken][SCIT-NPI] The characters show "" when enter "12345"(Arabic) in the registration page. - HPXWC-5824\[SFT_MPH][DisplayControl][Accessibility] Narrator cannot read any feature on Display Control module using finger touch and clicking through mouse - HPXWC-5824\[SFT_MPH][DisplayControl][Accessibility] Narrator cannot read any feature on Display Control module using finger touch and clicking through mouse - HPXWC-6186\[Account][PCDevice] Home/Device page mashup after idle time - HPXWC-5788\[SFT_MPH][SmartExp][L10N] 'Auto Screen Dimming' string is not localized in Greek-EL language - HPXWC-5967\Feature-specific (PCAudio? MaxxAudioAPOShellRPC64.dll) binary embedded in the Shell (UWP or DesktopExtension) - HPXWC-5973\[Audio] EQ is not showing correct units on Grogu and London | G13: 1. Home Page 2. Video Control - SmartCam 2 (if the system has SmartCam2 feature byte qj) - SmartCam 3.5.39.0 (if the system has SmartCam3 feature byte qM) 3. HP Programmable Key 4. Privacy alert 5. Auto Screen Dimming 6. Support 7. Settings | I13: V | J13: V | L13: V | M13: V | Y13: V | Z13: V | AA13: V | AB13: V | AC13: V | AD13: V | AE13: V | AF13: V | AG13: V | AH13: V | AI13: V | AJ13: V | AK13: V | AL13: V | AM13: V | AN13: V | AO13: V | AR13: V | AS13: V | AV13: V | AW13: V | AZ13: V
A14: 44970 | B14: HPX for CMIT | C14: Staging Build | D14: 25.42306.27.0.A.1 | E14: P014C9-B2L | F14: For 2023 NPI, CFR on or after 1/30 platforms Main changes: • HPXWC-6190\[Audio] Enhancement - Turn OFF "Restore Defaults" button within audio control on HPX 0.5 to support 09Feb23 release • HPXWC-5960\[Communications] Investigate to fix toggle button alignment issue • HPXWC-5396\[Home] Missing PC connect(5G) from home page • HPXWC-5865\[SFT_MPH][Homepage] Narrator is not able to read the selected text (control your pc header). • HPXWC-4401\[HighContrast] Turn on High Contrast theme, open one page, cannot see the Icon in the left menu • HPXWC-5778\[SFT_MPH][FirstUse][Privacy] About Your Privacy Page has not shown when all the consent value are set to unknown. • HPXWC-6149\[Offline] Error shows when disconnect the network. HPX does not work offline. • HPXWC-6239\[5G] HPX crashed when use cellular data connection • HPXWC-6142\[AudioControl] Dynamic Audio content is not classified correctly • HPXWC-6063\[AudioControl] Audio presets default option is "Voice" instead of "Music" in Arti-A machine • HPXWC-4399\[PCConnect] Cannot navigate to the PCConnect module through the link of PC device module • JWEB-5894\[Analytics] [Instrumentation] Privacy Setting Analytics Data • HPXWC-6120\[FirstUse][HPID] HP registration and HP privacy missing when launch HPX at the first time • HPXWC-5165\[SFT_MPH][SmartExp][L10N] UI is not localized for Smart Experiences cards in Bahasa Indonesian (ID) language • HPXWC-6202\[Core] Support is missing on Home page | G14: 1. Home Page 2. Video Control - SmartCam 2 (if the system has SmartCam2 feature byte qj) - SmartCam 3.5.39.0 (if the system has SmartCam3 feature byte qM) 3. HP Programmable Key 4. Privacy alert 5. Auto Screen Dimming 6. Support 7. Settings | I14: V | J14: V | L14: V | M14: V | Y14: V | Z14: V | AA14: V | AB14: V | AC14: V | AD14: V | AE14: V | AF14: V | AG14: V | AH14: V | AI14: V | AJ14: V | AK14: V | AL14: V | AM14: V | AN14: V | AO14: V | AR14: V | AS14: V | AV14: V | AW14: V | AZ14: V
A15: 44973 | B15: HPX for CMIT | C15: Production build | D15: 25.52307.21.0.A.1 | E15: P014C9-B2N | F15: For 2023 NPI, CFR on or after 1/30 platforms Main changes: Fixed issues • HPXWC-6200\ SIO2170743 - [NB][Iaso][SCIT-NPI] No response when used finger to click the pen icon in HPX\Devices\PC Device. • HPXWC-6326\[SFT_MPH][Homepage] The text content and image in the hero banner is overlapping on Arabic and Hebrew language. • HPXWC-5718\[SFT_MPH][OTA][HomePage] When navigate to HomePage it shows first Offline Message and it displays Home page • HPXWC-6238\ SIO2171018 - [SIT][SWT-SW][HPX0.5_OTA] HPX auto exit after unplug headset. • HPXWC-6143\[SFT_MPH][OTA][Support] Intermittently Product number and serial number is not displayed in Support page • HPXWC-6351\On PC Device page, "Get Details" link is in English when Windows display language is in Chinese • HPXWC-6352\App crashed when continuously select Folder/file item from Dropdown on Programmable key • HPXWC-6191\Hamburger Menu holding element has the wrong corners • HPXWC-6139\SIO2170302 - [DigdugR] myHP content character will shows "..." after change text size in Setting/Accessibility. • HPXWC-5473\[HPPK][PPR] Modal window: Application, margins and spacing are not as specified • Fixed user store: • Add back audio DLL. • Add language support for sr-BA • HPXWC-6157\Add device mode button in PCSystemControl module • HPXWC-6008\Ability to override features flags with manageability tools • HPXWC-6248\[Home Page] Remove native code setting the Banner heading. • HPXWC-6357\Implement translated strings for February received - PCDevicePage • HPXWC-6306\Add get mode and sanity check in System Control nuget | G15: 1. Home Page 2. Video Control - SmartCam 2 (if the system has SmartCam2 feature byte qj) - SmartCam 3.5.39.0 (if the system has SmartCam3 feature byte qM) 3. HP Programmable Key 4. Privacy alert 5. Auto Screen Dimming 6. Support 7. Settings | I15: V | J15: V | L15: V | M15: V | Y15: V | Z15: V | AA15: V | AB15: V | AC15: V | AD15: V | AE15: V | AF15: V | AG15: V | AH15: V | AI15: V | AJ15: V | AK15: V | AL15: V | AM15: V | AN15: V | AO15: V | AR15: V | AS15: V | AV15: V | AW15: V | AZ15: V
... A29: 45121 | B29: HPX for CMIT | C29: Production build | D29: 25.52328.396.0.A.1 | E29: P0151E-B2J | F29: Main changes: P1: • HPXSUP-1887 [OCFResources]-HTML Path error, about page is blank now. Stories: • HPXSUP-1861 [Veracode] Remove useless files of HPNetworkCheck • HPXWC-11635 [AudioControl][Bopeep] Adaptive audio module should grey out when we select Music and Voice option | G29: 1. Home Page 2. Video Control - SmartCam 3.v3.2307.86 3. HP Programmable Key 4. Privacy alert 5. Auto Screen Dimming 6. Support 7. Settings | I29: V | J29: V | L29: V | M29: V | Y29: V | Z29: V | AA29: V | AB29: V | AC29: V | AD29: V | AE29: V | AF29: V | AG29: V | AH29: V | AI29: V | AJ29: V | AK29: V | AL29: V | AM29: V | AN29: V | AO29: V | AR29: V | AS29: V | AV29: V | AW29: V | AZ29: V
A30: 45128 | B30: HPX for CMIT | C30: Production build | D30: 25.52329.430.0.A.1 | E30: P0151E-B2L | F30: Main changes: • Update SmartCam to v3.2307.96 • HPXAPPS-975 [Housekeeping] Update README for @hp-af/react-native-netinfo library • HPXWC-12134 [USA-Video] Integrate HPPVForMyHP_Release_v3.2307.96.21703.zip into HPX 2023.07.B. Please launch with HPPVLauncher.exe. • HPXAPPS-1330 [SFT_MPH][OTA][Core] When we minimized and launch HPX App we observed that text is merged (Only on Windows 10) • HPXAPPS-786 Replace custom logging with HP.ApplicationFramework.Logging in Desktop Extension • HPXAPPS-987 [CGQA][Feedback] "select a star rating before you submit " validation location is not matching same as figma design • HPXWC-11912 [SFT_MPH][SmartExp] Toggle button is not persistent on relaunching HPX app while the module dialogue is opened • HPXWC-11906 [SFT_MPH][SmartExp] Overlap between 'Cancel' and 'Continue' button on resizing the HPX window to small | G30: 1. Home Page 2. Video Control - SmartCam v3.2307.96 3. HP Programmable Key 4. Privacy alert 5. Auto Screen Dimming 6. Support 7. Settings | I30: V | J30: V | L30: V | M30: V | Y30: V | Z30: V | AA30: V | AB30: V | AC30: V | AD30: V | AE30: V | AF30: V | AG30: V | AH30: V | AI30: V | AJ30: V | AK30: V | AL30: V | AM30: V | AN30: V | AO30: V | AP30: V | AQ30: V | AR30: V | AS30: V | AV30: V | AW30: V | AZ30: V
A31: 45135 | B31: HPX for CMIT | C31: Production build | D31: 25.52330.450.0.A.1 | E31: P0151E-B2M | F31: Main changes: • HPXWC-12366 [Perf] - System Controls -need to toggle off Commercial and visible only for Consumer | G31: 1. Home Page 2. Video Control - SmartCam v3.2307.96 3. HP Programmable Key 4. Privacy alert 5. Auto Screen Dimming 6. Support 7. Settings | I31: V | J31: V | L31: V | M31: V | Y31: V | Z31: V | AA31: V | AB31: V | AC31: V | AD31: V | AE31: V | AF31: V | AG31: V | AH31: V | AI31: V | AJ31: V | AK31: V | AL31: V | AM31: V | AN31: V | AO31: V | AP31: V | AQ31: V | AR31: V | AS31: V | AV31: V | AW31: V | AZ31: V
A32: 45163 | B32: HPX for CMIT | C32: Production build | D32: 25.52334.593.0.A.1 | E32: P0151E-B2P | F32: Main changes: • Update SmartCam to 3.2307.98 • HPXAPPS-2012 [SFT_MPH][OTA][Core][DarkMode] In Navigation bar, when we click on any module name, color is changing in blue • HPXAPPS-2078 [Services-UI] Cannot restore Mouse sensitivity's value • HPXAPPS-2017 [MyAccount] My Account page is empty • HPXAPPS-2115 [HPX] HPX crashes when clicking 'pc device' page after goes in to any module page on latest build. • HPXAPPS-2070 [HPX] Most toggles change to off (from On) after relaunch HPX. (SmartExp, Privacy Alert,PenControl,RGB and 5G). • HPXAPPS-947 [ServiceRouting] Profile icon shows empty after clicking on any tiles on Home page • HPXAPPS-2163 [SFT_MPH][Registration] By clicking 'HP Privacy Statement' link is not navigating to browser/Not functional at all. • HPXAPPS-2264 Clicking on the account icon does nothing • HPXAPPS-1765 [SFT_MPH][OTA_FFT][Core] After pressing F12 hotkey, "Devices" page is not opening in left nav. • HPXAPPS-2425 [SNN] When user does not see Strictly Necessary Notice in UI, the registry NecessaryNoticeShown is set to 1 • HPXAPPS-2389 [SFT_MPH][OTA_FFT][HPPK] Observed loading state after pressing F12 key • HPXAPPS-2097 [Settings] React native tab view doesn't work with multiple routes (Patch) • HPXAPPS-2036 Create Publish nexus modules docs • HPXAPPS-525 [HomePage] Re-enable the "Next Steps" section of the Home page • HPXSUP-1747 [Translation] Support 7 new languages for diagnostics tools • HPXAPPS-2142 Dark mode support for Storybook module • HPXAPPS-2150 [Communications] Integrate translation for the strings in Settings page • HPXAPPS-1798 Implement the Landing page for HPID • HPXAPPS-1000 [Communication][Settings][UI]Develop Feedback Tab UI in Settings Native View • HPXWC-12819 [ContextAware] [AppSettings] Fetching installed applications' list from library • HPXWC-12742 [Pen][Commercial] Observation found on Narrator • HPXAPPS-782 Build with NuGet packages • HPXWC-12766 [Pen][Commercial] - Support sentence for titles and header string • HPXAPPS-1801 Implement accessibility, narrator, highcontrast and darkmode for HPID Landing page • HPXWC-10254 [Application Settings] [Context Aware] [NFR] Support Accessibility (WER) Requirements • HPXAPPS-1799 Integrate the HPID Login Dialog with the Sign In button • HPXAPPS-1623 [SIO2195914] HPX always open automatically after the unit restarts. • HPXAPPS-1800 Add analytics to the Landing screen of the HPID Login • HPXAPPS-1563 Add some animation after the submit feedback • HPXWC-12199 [SFT_MPH][SmartExp][Tab] Tab is not focusing model dialogue box area • HPXAPPS-1754 [Core][HPPK][Deeplink] Programmable Key deeplink broken • HPXWC-12509 [PCDevice][HighContrast] Some text are missing on PCdevice header after applying contrast themes. • HPXAPPS-252 SIO2169521 Missing "Use the HP Virtual Assistant" and "Run hardware diagnostics" under HPX/Support/Device support/Guided troubleshooting with build • HPXWC-12326 [SmartExp] Unable to select the tooltips icon with the mouse and check AUID using Accessibility Insights tool • HPXAPPS-1787 [SFT_MPH][Registration] 'Skip this step' spacing is not as per Figma. • HPXAPPS-1088 [HighContrast] The hyperlink inside PC modal is not displaying in high contrast modes • HPXAPPS-1085 [HighContrast][PCDevice] Color of Get details link and View data collected are not changing as per theme selection. • HPXAPPS-243 [Registration][DarkMode] Hover over the inputs fields and clickable buttons are not as expected on registration page in dark mode • HPXWC-12198 [SFT_MPH][OTA_FFT][HPPK][HighContrast] Numbers are not visible when we apply high contrast themes • HPXAPPS-1717 [SFT_MPH][OTA][Services] HP privacy link is not highlighting with underline in warranty-View data collected • HPXAPPS-691 [ServiceRouting][Home] Card Icon are missing when we navigate back to home page from Interstitial screen. • HPXAPPS-1718 [SFT_MPH][OTA][PCDevice][TAB] When we increase text size, Text is not highlighting properly using TAB key • HPXAPPS-2013 [SFT_MPH][OTA][Home][TabNavigation] Able to navigate to non-pressable events like control your PC • HPXAPPS-1038 [SFT_MPH][PCDevice] Text cut-off and overlapping observed when increasing text size to maximum • HPXAPPS-1180 [SFT_MPH][Services] Able to redirect to myaccount page and displays error while clicked on go to my account immediately after clicking on sign-out • HPXAPPS-2022 [High Contrast] myHP is showing partial effect when we switch between different high contrast modes • HPXAPPS-1073 [SFT_MPH][PCDevice] Not able to navigate "Allow personalized support" window in Get Details section by using keyboard. • HPXWC-12642 [Application Settings][Context Aware] Close Button (X) in Delete App Modal is not same in certain resolutions • HPXWC-12440 [SIO2197127] The information under Devices lost in HPX with Corporate-Ready Image after restart unit. • HPXAPPS-2210 [Settings] SNN shows up and disappears in settings Privacy tab • HPXAPPS-1081 [CGQA]Profile icon should be transparent without any square background • HPXWC-12456 [Application Settings] [Context Aware] Develop a method for checking whether context-aware service is running • HPXWC-11728 [SIO2193672] : It would need 5~10s to response after select the Application option for the first time in MyHP/Programmable Key • HPXAPPS-1699 [SFT_MPH][Core][Narrator] Narrator is reading as pane for all modules • HPXAPPS-2193 [SFT_MPH][OTA][HomePage][Tab] Entire Home page is selected while tab navigating • HPXWC-12650 [PCDevice] If we make text size to largest then product number value click tooltip is not as per figma • HPXAPPS-1399 [Service] myHP stuck loading when launched from HPID . • HPXAPPS-1797 [Privacy] [High Contrast] Hover over manage option, the text doesn't show hover effect • HPXAPPS-1796 [Privacy] [High Contrast] Manage option button is displayed in the box on high contrast modes • HPXWC-12375 [Keyboard][HighContrast] Some text are missing on Keyboard header after applying contrast themes. • HPXAPPS-1333 [SFT_MPH][HighContrast][PCDevice] Observed black bars on hover over the cards on applying high contrast themes. • HPXAPPS-2164 [SFT_MPH][Registration] In Registration when we hover on "Skip this step" Button we are able to see underline. • HPXAPPS-2166 [SFT_MPH][OTA_FFT][HomePage] Narrator is narrating the "view all controls" as custom instead of link/button. • HPXAPPS-2243 [SettingsNative] Settings tabs is not clickable properly • HPXAPPS-1603 [SettingsNativeView] In settings in Highcontrast themes there is no border separation in Header • HPXWC-12632 Intermittently foreground application is not getting highlighted in the app setting bar • HPXAPPS-1760 HPX hangs when deeplink incorrect • HPXAPPS-1787 [SFT_MPH][Registration] 'Skip this step' spacing is not as per Figma. • HPXAPPS-2098 Fix spacing between bell icon and profile icon as per Figma • HPXAPPS-2099 Fix spacing from right to profile icon on top bar • HPXAPPS-2100 Fix spacing between back arrow and myHP logo as per Figma • HPXAPPS-253 SIO2169276 - [Sandwalker][DarkMode] myHP warning messages are difficult to read in dark mode • HPXAPPS-1613 [SFT_MPH][OTA_FFT] Not able to select the hyperlink in Get Details section by using tab and shift+tab keys. • HPXAPPS-2245 [HighContrast][PCDevice][Win11] Card icons are not visible on applying Aquatic contrast themes. • HPXWC-12724 [SFT_MPH][SmartExp] Able to access Smart experiences UI using Restore default button when the camera is disabled from device manager • HPXWC-12635 [SFT_MPH][SmartExp][Tab] Tab is focusing two times for tool tips • HPXAPPS-198 [CGQA] HP registration page is not localized in ID-ID language • HPXAPPS-2194 [SFT_MPH][OTA_FFT][HighContrast][Core] On applying high contrast themes, hyperlink is getting invisible in Get details section. • HPXAPPS-2191 [Offline] The Hyperlink 'Connect' on the offline banner is not aligned with the preceding string. • HPXWC-11909 [ExtKeyboard][Accessibility][HighContrast] Configure key icon can not see clear when turn on high contrast theme and hover on key in keyboard. • HPXSUP-1859 [Support][Cybersec][STS2023-1407] - PESecurity tool - Error - Safe exception error handler - SafeSEH • HPXAPPS-1722 [SignIn] Support home is totally blank when sign in on home page • HPXAPPS-1767 [DeepLink] Once open HPX by press Hotkey, and then Navigation doesn't work • HPXWC-12831 [SFT_MPH][PCDevice] Observed the Product number and Serial number popup window is blinking on Cybug platform. • HPXAPPS-1720 [SFT_MPH][First Use Privacy][Services] Tab and Narrator Placeholder is not covering properly at a time. • HPXAPPS-1080 [HighContrast] Profile Flyout has not observed High contrast themes properly. • HPXAPPS-248 [SFT_MPH][Core] Intermittently "myHP" Logo is missing. • HPXAPPS-1339 [NavigationBar] Sometimes, Navigation bar doesn't turn to Support when click the Support section under PC Device page • HPXAPPS-1081 [CGQA]Profile icon should be transparent without any square background • HPXSUP-2105 [Feedback] - Need translation for some strings in Feedback window for 7 languages • HPXAPPS-2087 [SFT_MPH][OTA][Settings] Link(text) in the about tab are not arranged and alligned properly on london platform • HPXWC-12950 [HPPK][AUID] Personalized text on programmable key has missing AUID • HPXAPPS-1107 [SFT_MPH][SmartExp] Able to navigate across the unfocused area through TAB key • HPXAPPS-1152 [Accessibility][Settings] Privacy and About page hyperlinks and selected text doesn't match High Contrast themes • HPXWC-12803 [SFT_MPH][ContextAware] Size difference seen on Cancel button in application page UI Compared to figma | G32: 1. Home Page 2. Video Control - SmartCam v3.2307.98 3. HP Programmable Key 4. Privacy alert 5. Auto Screen Dimming 6. Support 7. Settings | I32: V | J32: V | L32: V | M32: V | Y32: V | Z32: V | AA32: V | AB32: V | AC32: V | AD32: V | AE32: V | AF32: V | AG32: V | AH32: V | AI32: V | AJ32: V | AK32: V | AL32: V | AM32: V | AN32: V | AO32: V | AP32: V | AQ32: V | AR32: V | AS32: V | AV32: V | AW32: V | AZ32: V
A33: 45180 | B33: HPX for CMIT | C33: Staging 9A | D33: 25.42336.783.0.A.1 | E33: P0151E-B2R | F33: "NOTE: When testing, please turn off auto update in MS Store app first to avoid being automatically updated to the latest version on MS Store. Known Issue: • HPXAPPS-2810 [HPX][Home][RCBranch] There are no strings visible on Welcome Banner Changes: - Enable System Control, Battery Manager, AUdio Control - Update SmartCam to v3.2309.106 • HPXWC-13232 SIO2202874/SIO2203079 - The battery icon in HPX shows a different amount of power than the system's battery icon. • HPXAPPS-2714 [HPX][Home] Narrator is not reading the titles and the descriptions of the action cards • HPXAPPS-2675 [SFT_MPH][L10N][SettingsNative][Feedback] Settings Page shows empty when we apply Arabic/Hebrew Languages • HPXAPPS-2756 Support page cannot be loaded in the latest builds • HPXAPPS-2092 [HPX] myhp will crash directly after upgrading to 25.52331.464.0_MSIXUPLOAD from MS store • HPXWC-13088 [SFT_MPH][SmartExp] Buttons and links are not aligned properly on dialog box • HPXWC-12865 [Battery Manager][Native] API to read/write Maximize Battery Health • HPXAPPS-2333 [SettingsNativeview] Update settings view privacy tab with strictly necessary notice string • HPXAPPS-2488 Update Support tile on Home page for HP One launch - "24x7 Pro live support" • HPXWC-13120 [Battery Manager][UI] Responsive behavior for Consumer view • HPXWC-12810 [SFT_MPH][ContextAware][Accessbility] Narrator is not reading properly for Application page UI • HPXAPPS-2668 [SFT_MPH][HighContrast][Feedback] High Contrast is not applying properly for Submit Button. • HPXWC-13232 SIO2202874/SIO2203079 - The battery icon in HPX shows a different amount of power than the system's battery icon. • HPXWC-13089 [SFT_MPH][ContextAware][L10N] String is not localized on Chinees language • HPXAPPS-2738 [SFT_MPH][SettingsNative][Feedback] "Thank You" Banner is not dismissing when user enter data in input field • HPXWC-13354 [SFT_MPH][OTA_FFT][AudioControl] When we connect 3.5 mm jack we observe the difference in placing of presets string and tool tip icon. • HPXAPPS-2792 [SFT_MPH][SettingsNative][Feedback] AUID is not generating for "Submit Feedback Button" • HPXWC-13141 [SFT_MPH][ContextAware][Accessibility] Add application text cut-off seen when we make text size bigger • HPXAPPS-2670 [SFT_MPH][HomePage] Observed text cut off in Hero banner on minimizing the HPX app • HPXAPPS-2714 [HPX][Home] Narrator is not reading the titles and the descriptions of the action cards | G33: 1. Home Page 2. Video Control - SmartCam v3.2309.106 3. HP Programmable Key 4. Privacy alert 5. Auto Screen Dimming 6. Support 7. Settings 8. System Control 9. Battery Manager 10. Audio Control | I33: V | J33: V | L33: V | M33: V | N33: V | O33: V | P33: V | Q33: V | R33: V | S33: V | T33: V | U33: V | V33: V | Y33: V | Z33: V | AA33: V | AB33: V | AC33: V | AD33: V | AE33: V | AF33: V | AG33: V | AH33: V | AI33: V | AJ33: V | AK33: V | AL33: V | AM33: V | AN33: V | AO33: V | AP33: V | AQ33: V | AR33: V | AS33: V | AV33: V | AW33: V | AX33: V | AZ33: V | BB33: V
A34: 45194 | B34: HPX for CMIT | C34: 10A Staging | D34: 25.42338.826.0.A.1 | E34: P0151E-B2T | F34: "NOTE: When testing, please turn off auto update in MS Store app first to avoid being automatically updated to the latest version on MS Store. "NOTE: With json file to enable features in Staging build, please re-sign in after OOBE to trigger the enablement For 2024 NPI Platforms except Arizona Refresh Changes: - Workaround to Enable System Control, Battery Manager, AUdio Control after dashing • HPXAPPS-2913 myHP crashed on Willie when change language from English to France • HPXAPPS-2952 [HPX][Localization] Application not starting at all • HPXWC-13184 [SFT_MPH][Battery] When we disable Power control in F10, observe In-charging scheduler notifications are coming when we schedule the time • HPXWC-13268 [SFT_MPH][Battery] Improper battery percentage observed on battery module UI • HPXWC-13202 [Battery Manager][UI] UI changes as per updated figma • HPXWC-13118 [Battery Manager][UI] Responsive behavior for Battery Charge Manager • HPXWC-13119 [Battery Manager][UI] WER, narrator for Battery Charge Manager • HPXAPPS-2739 [SFT_MPH][OTA][HomePage][DarkMode] Observed White Space before loading "Get the Most Out of HP" Cards at the End of the HPX Application • HPXWC-13224 [SFT_MPH][ContextAware] Application cut-off seen in list while scrolling applications through Tab • HPXAPPS-3006 [Bell] App is not fetching any messages • HPXWC-13375 [SFT_MPH][OTA][PC Device] PN/SN pop up window is not navigating back to it's normal position after maximizing the screen from minimum. • HPXAPPS-188 [CGQA] Contrast theme is not applyed same as windows theme specification • HPXAPPS-2842 [SFT_MPH][Services][First Use][L10N] Learn more link is not working for Hebrew language. • HPXAPPS-2891 [SFT_MPH][Core] Intermittently "myHP" logo is shown in wrong position in top bar for RTL (Arabic and Hebrew) languages. • HPXAPPS-2926 [PCDevicePg] Clicking on "Support" card is not navigating to proper page • HPXAPPS-2926 [PCDevicePg] Clicking on "Support" card is not navigating to proper page • HPXAPPS-2800 [Bell] Narrator reads Bell Interstitial side bar Notification messages and pop up notification Flyout as custom • HPXWC-13759 SIO2201684 - The output character show i when use lowercase j to rename pen in HPX\Pen control. • HPXSUP-1873 Migrate react components of VA to native-base based RN components • HPXWC-13142 [SFT_MPH][ContextAware][Accessibility] Cancel button space is not proper when we make text size bigger on Win10 platform • HPXWC-13431 [ContextAware] After adding first application, the whole pane shifts downwards • HPXAPPS-3021 [SNN]NecessaryNoticeShown reg key not updated when app upgraded from previous non SNN supported version of hpx • HPXWC-13173 [localization] Some card description text in pc device module is cut off in fr-CA and es-MX languages | G34: 1. Home Page 2. Video Control - SmartCam v3.2309.106 3. HP Programmable Key 4. Privacy alert 5. Auto Screen Dimming 6. Support 7. Settings 8. System Control 9. Battery Manager 10. Audio Control | I34: V | J34: V | L34: V | M34: V | N34: V | O34: V | P34: V | Q34: V | R34: V | S34: V | T34: V | U34: V | V34: V | Y34: V | Z34: V | AA34: V | AB34: V | AC34: V | AD34: V | AE34: V | AF34: V | AG34: V | AH34: V | AI34: V | AJ34: V | AK34: V | AL34: V | AM34: V | AN34: V | AO34: V | AP34: V | AQ34: V | AR34: V | AS34: V | AV34: V | AW34: V | AX34: V | AZ34: V | BB34: V
A35: 45194 | B35: HPX for CMIT | C35: 9A Production RC6 | D35: 25.52339.812.0.A.1 | E35: P0151E-B2U | F35: "NOTE: When testing, please turn off auto update in MS Store app first to avoid being automatically updated to the latest version on MS Store. For 2024 NPI Arizona Refresh Only Changes: • HPXAPPS-3248: [Settings][RC Branch] Version No. in About tab shows Null • HPXAPPS-3247: [HP Registration][RC Branch] Seeing HP Reg. page on every app launch • HPXAPPS-3254 [HPX][HPID][Production] User cannot sign up successful when user completed sign up in browser. | G35: 1. Home Page 2. Video Control - SmartCam v3.2309.106 3. HP Programmable Key 4. Privacy alert 5. Auto Screen Dimming 6. Support 7. Settings | I35: V | J35: V | L35: V | M35: V | Y35: V | Z35: V | AA35: V | AB35: V | AC35: V | AD35: V | AE35: V | AF35: V | AG35: V | AH35: V | AI35: V | AJ35: V | AK35: V | AL35: V | AM35: V | AN35: V | AO35: V | AP35: V | AQ35: V | AR35: V | AS35: V | AV35: V | AW35: V | AZ35: V
A36: 45201 | B36: HPX for CMIT | C36: 9A Production RC8 | D36: 25.52339.829.0.A.1 | E36: P0151E-B2W | F36: "NOTE: When testing, please turn off auto update in MS Store app first to avoid being automatically updated to the latest version on MS Store. For 2024 NPI Arizona Refresh Only Changes: • HPXAPPS-2209 [SFT_MPH][OTA_FFT][DisplayControl][AIO] Few second delay loading Display Control and other cards under Home page and PC Device page • HPXWC-13823 [Pen] Pen Control Module is not visible in HPX application | G36: 1. Home Page 2. Video Control - SmartCam v3.2309.106 3. HP Programmable Key 4. Privacy alert 5. Auto Screen Dimming 6. Support 7. Settings | I36: V | J36: V | L36: V | M36: V | Y36: V | Z36: V | AA36: V | AB36: V | AC36: V | AD36: V | AE36: V | AF36: V | AG36: V | AH36: V | AI36: V | AJ36: V | AK36: V | AL36: V | AM36: V | AN36: V | AO36: V | AP36: V | AQ36: V | AR36: V | AS36: V | AV36: V | AW36: V | AZ36: V
A37: 45201 | B37: HPX for CMIT | C37: 10A Staging | D37: 26.42339.861.0.A.1 | E37: P0151E-B2X | F37: "NOTE: When testing, please turn off auto update in MS Store app first to avoid being automatically updated to the latest version on MS Store. "NOTE: With json file to enable features in Staging build, please re-sign in after OOBE to trigger the enablement For 2024 NPI Platforms except Arizona Refresh Changes: • Update SmartCam to v3.2310.108 • HPXWC-13160 [SFT_MPH][Battery] Threshold percentage dropdown showing blank when we re-enable 'Power control' option in Bios settings • HPXWC-13875 [DisplayControl] The alignment of slider icons and app icons is not correct • HPXAPPS-3254 [HPX][HPID][Production] User cannot sign up successful when user completed sign up in browser. • HPXAPPS-3432 [Registration] Registration page missing • HPXAPPS-3354 [PCDevice] Unable to see most of the modules cards in PC device page action section • HPXWC-13502 [Touchpad][UI] Corresponding UI when 'Touchpad' turn off in OS settings. • HPXWC-13774 [System Control][Middleware] - API to read Smart Sense V2 support. • HPXWC-13574 [System Control][Middleware] - Redux and Saga implementation for Smart Sense V2 • HPXWC-13575 [System Control][UI] - Display Smart Sense V2 modes • HPXWC-13573 [System Control][Native] - API to read Smart Sense V2 support. • HPXWC-13475 [Pen control] complete Battery tool tip text not coming in inspect tool on consumer machine. • HPXAPPS-2597 [Analytics] SNN should be displayed as part of hpx startup flow • HPXWC-13128 [Sys control][ELP] code rollback | G37: 1. Home Page 2. Video Control - SmartCam v3.2310.108 3. HP Programmable Key 4. Privacy alert 5. Auto Screen Dimming 6. Support 7. Settings 8. System Control 9. Battery Manager 10. Audio Control | I37: V | J37: V | L37: V | M37: V | N37: V | O37: V | P37: V | Q37: V | R37: V | S37: V | T37: V | U37: V | V37: V | Y37: V | Z37: V | AA37: V | AB37: V | AC37: V | AD37: V | AE37: V | AF37: V | AG37: V | AH37: V | AI37: V | AJ37: V | AK37: V | AL37: V | AM37: V | AN37: V | AO37: V | AP37: V | AQ37: V | AR37: V | AS37: V | AV37: V | AW37: V | AX37: V | AZ37: V | BB37: V
A38: 45212 | B38: HPX for CMIT | C38: 10A Staging | D38: 26.42340.870.0.A.1 | E38: P015S9-B2A | F38: "NOTE: When testing, please turn off auto update in MS Store app first to avoid being automatically updated to the latest version on MS Store. "NOTE: With json file to enable features in Staging build, please re-sign in after OOBE to trigger the enablement For 2024 NPI Platforms except Arizona Refresh Changes: • Update SmartCam to v3.2310.110 • HPXAPPS-3652 "isUwpInstalled" from @enabling-services/systemproperties is broken • HPXWC-13956 [System Control][Fusion CASL SDK] - Update API to read Smart Sense V2 support • HPXWC-14059 Integrate Transations for Battery manager and System Control • HPXWC-13130 [UserDetect] implement RTK camera feature • HPXAPPS-3165 [SIO2207476] HPX first use flow(1st Launch in online mode) is not localized with EN language image(A2N). • HPXAPPS-3378 [PPR][NativeSetting][Feedback] Misalignment observed for the "text box(Provide any additional feedback)" and "Submit Feedback" • HPXAPPS-2797 [SFT_MPH][FirstUse][Services] Tab order is not navigating on each component of the page. • HPXAPPS-3171 [HomePage][CEC] Observed a cutoff on PC diagnostic Tools Card on resizing screen to smallest mode. • HPXWC-13303 [AudioControl][SpeakerConfig] Seeing cutoff on ft/db dropdowns on resizing screen to smallest mode. | G38: 1. Home Page 2. Video Control - SmartCam v3.2310.110 3. HP Programmable Key 4. Privacy alert 5. Auto Screen Dimming 6. Support 7. Settings 8. System Control 9. Battery Manager 10. Audio Control | I38: V | J38: V | L38: V | M38: V | N38: V | O38: V | P38: V | Q38: V | R38: V | S38: V | T38: V | U38: V | V38: V | Y38: V | Z38: V | AA38: V | AB38: V | AC38: V | AD38: V | AE38: V | AF38: V | AG38: V | AH38: V | AI38: V | AJ38: V | AK38: V | AL38: V | AM38: V | AN38: V | AO38: V | AP38: V | AQ38: V | AR38: V | AS38: V | AV38: V | AW38: V | AX38: V | AZ38: V | BB38: V
A39: 45219 | B39: HPX for CMIT | C39: 11A Staging | D39: 27.42342.923.0.A.1 | E39: P015S9-B2B | F39: "NOTE: When testing, please turn off auto update in MS Store app first to avoid being automatically updated to the latest version on MS Store. "NOTE: With json file to enable features in Staging build, please re-sign in after OOBE to trigger the enablement For 2024 NPI and 2024 Refresh CQ1 platforms Changes: • HPXWC-13592 [SFT_MPH][OTA][AudioControl] HPX application crashes after plugin and plug out of USB Headset in Audio control • HPXWC-13569 [Display][Native] - Implement an event for brightness • HPXWC-13885 [Display][UI] - [Display][UI]Make Use HDR functionality in line with UX/UX • HPXWC-14250 [HPPK] Design & refactor HPPK Main container for NEW UI • HPXWC-14383 [Pen][Commercial] Fix bugs from versions V1 and V2 • HPXWC-12894 [SFT_MPH][PowerManager][Battery] On relaunching the HPX application or navigate from other modules. Battery percentage will change from 0% to current percentage • HPXAPPS-2204 [High Contrast] [Left Nav] Switching between high contrast modes, the selected tab shows the previous high contrast effect • HPXAPPS-4054 [SFT_MPH][OTA][Core][HighContrast] myHP Strings color is changing for 1-2 seconds in top left • HPXWC-14238 [Pen][Commercial] PPR review Observation for update UI layout feature • HPXAPPS-3668 [SFT_MPH][OTA][HomePage][Tab] Navigate through tab in Home page, text cut off of external cards is observed • HPXAPPS-3978 [HPX][SNN]: Link misalignment on SNN startup screen when text size is Maximum • HPXAPPS-4028 [HPX][SNN]: Text lines are congested on the SNN startup screen when the text size is set to maximum • HPXAPPS-4089 [SFT_MPH][Homepage] Nonactionable strings are getting highlighting when navigating through keyboard. • HPXAPPS-4112 [HPX][AUID] 'Connect' link in the 'You're offline' message lacks an AUID • HPXAPPS-3044 [SFT_MPH][Battery][L10N] The tool tip edge showing opposite side and on resize the HPX window tool tip flicker while hover tool tip in HE language • HPXAPPS-3976 [BatteryManager] Tooltip info is not aligned to tooltip icon with Hebrew and Arabic languages. | G39: 1. Home Page 2. Video Control - SmartCam v3.2310.110 3. HP Programmable Key 4. Privacy alert 5. Auto Screen Dimming 6. Support 7. Settings 8. System Control 9. Battery Manager 10. Audio Control 11. Pen | I39: V | J39: V | L39: V | M39: V | N39: V | O39: V | P39: V | Q39: V | R39: V | S39: V | T39: V | U39: V | V39: V | Y39: V | Z39: V | AA39: V | AB39: V | AC39: V | AD39: V | AE39: V | AF39: V | AG39: V | AH39: V | AI39: V | AJ39: V | AK39: V | AL39: V | AM39: V | AN39: V | AO39: V | AP39: V | AQ39: V | AR39: V | AS39: V | AV39: V | AW39: V | AX39: V | AZ39: V | BA39: V | BB39: V
